Workbook

Sheet README_SOTP
B2: Vinci SA — Sum-of-the-parts valuation model (valuation date 30 Jun 2026 · price as of 16 Sep 2026)
B4: Investment logic
B5: Vinci is a portfolio of assets with very different economics: French motorway concessions that revert to the State at no cost (Escota 2032, Cofiroute 2034, ASF 2036), long-dated or freehold airports, and going-concern energy and construction businesses.
B6: A single perpetual DCF cannot capture finite contract lives, so each business is valued separately with the method that fits its legal and economic nature, then aggregated.
B7: Architecture
B8: Finite concessions (Autoroutes, OMA, other airports, other concessions): cash flows to contract end, TV = 0 — the same approach Vinci uses in its own impairment tests (FS 2025, Note E).
B9: Going concerns (freehold Gatwick + Edinburgh, VINCI Energies, Cobra IS, VINCI Construction): explicit forecast + Gordon TV with normalised capex. VINCI Immobilier at book capital employed.
B10: Each block has its own discount rate. Bridge at 30 Jun 2026: net debt, equity-method investments, net-of-tax pensions, third-party shares of Gatwick/Edinburgh/OMA on implied equity value, other minorities at book. Lease repayments sit inside FCF, so lease liabilities are not deducted.
B11: Sheets: Inputs → Autoroutes / Airports / Other_Concessions / Energy_Construction → SOTP (valuation, per-share build, checks, sensitivity). Historicals holds the FY2023–25 statements.
B12: Sources: VINCI FY2025 consolidated financial statements (Notes C.1.2, E, F.12, I.23.5, 29); 2025 Universal Registration Document (portfolio table, revenue by network); Half-year financial report 2026.
B13: Known limitations
B14: 1) No network-level accounts for ASF/Escota/Cofiroute: segment margins, capex and D&A applied pro rata to revenue. 2) Airport margins are segment averages. 3) "Other airports" and "Other concessions" use one weighted end date each.
... B16: 6) Discount rates are judgement inputs (yellow) — see SOTP sensitivity. 7) Cobra IS renewables EBITDA from current build-out not modelled explicitly.

Sheet SOTP
B2: Vinci SA — Sum-of-the-parts valuation (EUR m)
B3: =CONCATENATE("Valuation date ",TEXT(Inputs!$C$5,"dd-mmm-yyyy")," · balance sheet at 30 Jun 2026 · lease repayments inside FCF") -> Valuation date 30-Jun-2026 · balance sheet at 30 Jun 2026 · lease repayments inside FCF
B5: Block | C5: Method | D5: Life / TV | E5: WACC | F5: EV (100%) | G5: % of EV | H5: EV/EBITDA 26E
B6: ASF | C6: Finite-life DCF, TV = 0 | D6: Ends 2036 | E6: =Autoroutes!$C$12 -> 0.065 | F6: =Autoroutes!$C$38 -> 16324.916 | G6: =F6/$F$18 -> 0.16871021 | H6: =Autoroutes!$C$40 -> 5.8891906
B7: Escota | C7: Finite-life DCF, TV = 0 | D7: Ends 2032 | E7: =Autoroutes!$C$54 -> 0.065 | F7: =Autoroutes!$C$80 -> 2669.7173 | G7: =F7/$F$18 -> 0.027590252 | H7: =Autoroutes!$C$82 -> 3.9375724
B8: Cofiroute | C8: Finite-life DCF, TV = 0 | D8: Ends 2034 | E8: =Autoroutes!$C$96 -> 0.065 | F8: =Autoroutes!$C$122 -> 5885.7573 | G8: =F8/$F$18 -> 0.060826489 | H8: =Autoroutes!$C$124 -> 4.9538966
B9: Arcour, Arcos & A86 Duplex | C9: Finite-life DCF, TV = 0 | D9: Ends 2070 (A86: 2086) | E9: =Autoroutes!$C$138 -> 0.065 | F9: =Autoroutes!$C$164 -> 1567.1769 | G9: =F9/$F$18 -> 0.016196024 | H9: =Autoroutes!$C$166 -> 13.970359
B10: Gatwick + Edinburgh (freehold, 50.01%) | C10: DCF to 2035 + Gordon TV (freehold) | D10: Freehold | E10: =Airports!$C$12 -> 0.075 | F10: =Airports!$C$38 -> 14949.534 | G10: =F10/$F$18 -> 0.15449628 | H10: =Airports!$C$40 -> 13.279555
B11: OMA Mexico (to 2048, 29.99%) | C11: Finite-life DCF, TV = 0 | D11: Ends 2048 | E11: =Airports!$C$54 -> 0.095 | F11: =Airports!$C$80 -> 3105.9041 | G11: =F11/$F$18 -> 0.032098035 | H11: =Airports!$C$82 -> 7.583845
B12: Other fully consolidated airports (ANA, Aerodom, Lyon, Belgrade, Brazil…) | C12: Finite-life DCF, TV = 0 | D12: Weighted end ~2058 | E12: =Airports!$C$96 -> 0.08 | F12: =Airports!$C$122 -> 14811.109 | G12: =F12/$F$18 -> 0.15306573 | H12: =Airports!$C$124 -> 9.4479866
B13: Other concessions (VINCI Highways etc.) | C13: Finite-life DCF, TV = 0 | D13: Weighted end ~2050 | E13: =Other_Concessions!$C$12 -> 0.08 | F13: =Other_Concessions!$C$38 -> 4138.1812 | G13: =F13/$F$18 -> 0.042766125 | H13: =Other_Concessions!$C$40 -> 11.422989
B14: VINCI Energies | C14: 5-yr DCF + Gordon TV | D14: Going concern | E14: =Energy_Construction!$C$12 -> 0.075 | F14: =Energy_Construction!$C$38 -> 19042.164 | G14: =F14/$F$18 -> 0.19679166 | H14: =Energy_Construction!$C$40 -> 8.859419
B15: Cobra IS | C15: 5-yr DCF + Gordon TV | D15: Going concern | E15: =Energy_Construction!$C$54 -> 0.09 | F15: =Energy_Construction!$C$80 -> 3821.9922 | G15: =F15/$F$18 -> 0.039498463 | H15: =Energy_Construction!$C$82 -> 4.5873869
B16: VINCI Construction | C16: 5-yr DCF + Gordon TV | D16: Going concern | E16: =Energy_Construction!$C$96 -> 0.08 | F16: =Energy_Construction!$C$122 -> 9338.6104 | G16: =F16/$F$18 -> 0.096510075 | H16: =Energy_Construction!$C$124 -> 4.4205229
B17: VINCI Immobilier | C17: Book capital employed (1.0x) | D17: n.a. | F17: =Inputs!$C$27 -> 1108 | G17: =F17/$F$18 -> 0.01145065
B18: Enterprise value of consolidated businesses | F18: =SUM(F6:F17) -> 96763.062 | G18: =SUM(G6:G17) -> 1 | H18: =F18/(Autoroutes!$D$22+Autoroutes!$D$64+Autoroutes!$D$106+Autoroutes!$D$148+Airports!$D$22+Airports!$D$64+Airports!$D$106+Other_Concessions!$D$22+Energy_Construction!$D$22+Energy_Construction!$D$64+Energy_Construction!$D$106) -> 7.2696232
B20: Plus: equity-method investments (book) | F20: =Inputs!$C$17 -> 2051
B21: Less: net financial debt (30 Jun 2026) | F21: =-Inputs!$C$12 -> -22450
B22: Less: employee-benefit provisions, net of tax | F22: =-Inputs!$C$18*(1-Inputs!$C$11) -> -867.398
B23: Less: third-party share of Gatwick + Edinburgh (implied equity) | F23: =-Inputs!$C$25*MAX(0,F10-Inputs!$C$23) -> -2087.8491
B24: Less: third-party share of OMA (implied equity) | F24: =-Inputs!$C$26*MAX(0,F11-Inputs!$C$24) -> -1242.6104
B25: Less: other non-controlling interests (book) | F25: =-(Inputs!$C$19-Inputs!$C$20-Inputs!$C$21-Inputs!$C$22) -> -670
B26: EQUITY VALUE attributable to Vinci shareholders | F26: =F18+SUM(F20:F25) -> 71496.204
B27: Diluted shares (m) = issued × (1 − treasury %) + performance shares | F27: =Inputs!$C$7*(1-Inputs!$C$8)+Inputs!$C$9 -> 561.91309
B28: IMPLIED VALUE PER SHARE (EUR) | F28: =F26/F27 -> 127.23712
B29: Current share price (EUR) — see Inputs | F29: =Inputs!$C$6 -> 112.3
B30: Implied upside / (downside) | F30: =F28/F29-1 -> 0.13301089
B33: Value per share by block (EUR, before bridge items)
B34: ASF | F34: =F6/$F$27 -> 29.052387
B35: Escota | F35: =F7/$F$27 -> 4.7511214
B36: Cofiroute | F36: =F8/$F$27 -> 10.474498
B37: Arcour, Arcos & A86 Duplex | F37: =F9/$F$27 -> 2.7890023
B38: Gatwick + Edinburgh (freehold, 50.01%) | F38: =F10/$F$27 -> 26.604708
B39: OMA Mexico (to 2048, 29.99%) | F39: =F11/$F$27 -> 5.5273746
B40: Other fully consolidated airports (ANA, Aerodom, Lyon, Belgrade, Brazil…) | F40: =F12/$F$27 -> 26.358362
B41: Other concessions (VINCI Highways etc.) | F41: =F13/$F$27 -> 7.3644507
B42: VINCI Energies | F42: =F14/$F$27 -> 33.888095
B43: Cobra IS | F43: =F15/$F$27 -> 6.8017498
B44: VINCI Construction | F44: =F16/$F$27 -> 16.619315
B45: VINCI Immobilier + bridge items per share | F45: =(F17+SUM(F20:F25))/$F$27 -> -42.99394
...

Sheet Inputs
B2: Vinci SA — SOTP global inputs (EUR m unless stated)
B3: Blue = hardcoded input · Black = formula · Green = link to another sheet · Yellow = key judgement / update before use
B4: Input | C4: Value | D4: Source / comment
B5: Valuation date (= latest balance sheet, H1 2026) | C5: 46203 | D5: Vinci Half-year financial report 2026 — balance sheet at 30 Jun 2026
B6: Share price (EUR), close 16 Sep 2026 | C6: 112.3 | D6: Euronext Paris closing price, 16 Sep 2026 (provided by FCO). Update for later dates.
B7: Shares issued (m), 30 Jun 2026 | C7: 585.8917 | D7: H1 2026 report, sec. 5: 585,891,697 shares
B8: Treasury shares, % of capital, 30 Jun 2026 | C8: 0.054 | D8: H1 2026 report, sec. 5: 5.4% (4.4% at 31 Dec 2025)
B9: Unvested performance shares (m) | C9: 7.65954 | D9: FY2025 consolidated FS, share-based payments note: 7,659,540 (treated as fully dilutive)
B10: Tax rate FY2026 (incl. French exceptional CIT surtax) | C10: 0.348 | D10: FY2025 ETR 34.8%; 2026 Finance Bill (art. 12) extends the surtax one more year — H1 2026 report, Note on surtax
B11: Tax rate FY2027+ (French statutory, surtax expired) | C11: 0.258 | D11: Vinci tax note: theoretical CIT rate 25.83%
B12: Net financial debt, 30 Jun 2026 | C12: 22450 | D12: H1 2026 report: €(22,450)m. Includes €152m buy-back liability. Leases excluded (see note below).
B13: of which Concessions incl. holdings | C13: -28353 | D13: H1 2026 segment note C.1.1 (net surplus / (debt))
B14: of which Energy Solutions | C14: 981 | D14: idem
B15: of which Construction | C15: 1902 | D15: idem
B16: of which Holding companies | C16: 3019 | D16: idem
... B27: VINCI Immobilier — value at book capital employed (1.0x) | C27: 1108 | D27: FY2025 segment note C.1.2: capital employed 1,108. Property developer: EBITDA 61 < leases 62 and H1 2026 revenue −17% → a DCF gives a meaningless negative value; book used instead.
B29: Lease treatment: lease repayments are deducted inside each block's free cash flow (post-IFRS 16 "EBITDAaL" logic), so lease liabilities are NOT deducted again in the bridge.
B30: Check: segment net debt sums to group net debt (±2 rounding) | C30: =IF(ABS(Inputs!$C$13+Inputs!$C$14+Inputs!$C$15+Inputs!$C$16+Inputs!$C$12)<=2,"OK","REVISAR") -> OK

Sheet Autoroutes
B2: Autoroutes — French motorway concessions valued to contract expiry, TV = 0
B4: ASF
B5: Base revenue FY2025 (EUR m) | C5: 3929 | D5: ASF network 2,731 km, 100%. Base revenue = FY2025 VINCI Autoroutes revenue by network (URD 2025: ASF 3,929 / Cofiroute 1,684 / Escota 961 / others 159). ASSUMPTION: segment margin (EBITDA 4,784 / revenue 6,733), D&A (1,503), capex (23 operating + 565 growth = 8.7%) and leases (12) applied pro rata to revenue — no network-level accounts available. FY2026 growth −0.7% = H1 2026 revenue trend (traffic −2.9%). FY2027+ 2.1% = Vinci's own average revenue growth over ASF's residual life (impairment note). Capex held at 8.7% to the end as a proxy for hand-back (biens de retour) obligations. WACC 6.5%: low-risk tolled infrastructure (Rf ~3.0%, ERP ~5.0%, beta ~0.75) plus ~50bp for French fiscal/regulatory risk (TELD tax, surtax, tariff risk). End date = 31 Dec of the contract year (FS Note F.12 gives the year only). Contracts revert to the State at no cost → no terminal value.
B6: Revenue growth FY2026 | C6: -0.007
B7: Revenue growth FY2027+ | C7: 0.021
B8: EBITDA margin (CFO before tax & financing / revenue) | C8: 0.7105
B9: D&A % revenue | C9: 0.2232
B10: Capex % revenue (operating + growth investments) | C10: 0.0873
B11: Lease repayments % revenue | C11: 0.0018
B12: Discount rate (post-tax WACC) | C12: 0.065
B13: Type: 1 = finite concession (TV = 0) · 0 = going concern | C13: 1
B14: Concession end date (finite only) | C14: 50040
B15: Last explicit year (going concern only) | C15: 0
B16: Terminal growth g (going concern only) | C16: 0
B17: Terminal capex % revenue (going concern only) | C17: 0
B19: Fiscal year | D19: 2026 | E19: 2027 | F19: 2028 | G19: 2029 | H19: 2030 | I19: 2031 | J19: 2032 | K19: 2033 | L19: 2034 | M19: 2035 | N19: 2036 | O19: 2037 | P19: 2038 | Q19: 2039 | R19: 2040 | S19: 2041 | T19: 2042 | U19: 2043 | V19: 2044 | W19: 2045 | X19: 2046 | Y19: 2047 | Z19: 2048 | AA19: 2049 | AB19: 2050 | AC19: 2051 | AD19: 2052 | AE19: 2053 | AF19: 2054 | AG19: 2055 | AH19: 2056 | AI19: 2057 | AJ19: 2058 | AK19: 2059 | AL19: 2060 | AM19: 2061 | AN19: 2062 | AO19: 2063 | AP19: 2064 | AQ19: 2065 | AR19: 2066 | AS19: 2067 | AT19: 2068 | AU19: 2069 | AV19: 2070
B20: Fraction of year in valuation (after val. date / before concession end) | D20: =IF($C$13=1,MAX(0,MIN(DATE(D$19,12,31),$C$14)-MAX(Inputs!$C$5+1,DATE(D$19,1,1))+1)/365,IF(D$19<=$C$15,(DATE(D$19,12,31)-MAX(Inputs!$C$5+1,DATE(D$19,1,1))+1)/365,0)) -> 0.50410959 | E20: =IF($C$13=1,MAX(0,MIN(DATE(E$19,12,31),$C$14)-MAX(Inputs!$C$5+1,DATE(E$19,1,1))+1)/365,IF(E$19<=$C$15,(DATE(E$19,12,31)-MAX(Inputs!$C$5+1,DATE(E$19,1,1))+1)/365,0)) -> 1 | F20: =IF($C$13=1,MAX(0,MIN(DATE(F$19,12,31),$C$14)-MAX(Inputs!$C$5+1,DATE(F$19,1,1))+1)/365,IF(F$19<=$C$15,(DATE(F$19,12,31)-MAX(Inputs!$C$5+1,DATE(F$19,1,1))+1)/365,0)) -> 1.0027397 | G20: =IF($C$13=1,MAX(0,MIN(DATE(G$19,12,31),$C$14)-MAX(Inputs!$C$5+1,DATE(G$19,1,1))+1)/365,IF(G$19<=$C$15,(DATE(G$19,12,31)-MAX(Inputs!$C$5+1,DATE(G$19,1,1))+1)/365,0)) -> 1 | H20: =IF($C$13=1,MAX(0,MIN(DATE(H$19,12,31),$C$14)-MAX(Inputs!$C$5+1,DATE(H$19,1,1))+1)/365,IF(H$19<=$C$15,(DATE(H$19,12,31)-MAX(Inputs!$C$5+1,DATE(H$19,1,1))+1)/365,0)) -> 1 | I20: =IF($C$13=1,MAX(0,MIN(DATE(I$19,12,31),$C$14)-MAX(Inputs!$C$5+1,DATE(I$19,1,1))+1)/365,IF(I$19<=$C$15,(DATE(I$19,12,31)-MAX(Inputs!$C$5+1,DATE(I$19,1,1))+1)/365,0)) -> 1 | J20: =IF($C$13=1,MAX(0,MIN(DATE(J$19,12,31),$C$14)-MAX(Inputs!$C$5+1,DATE(J$19,1,1))+1)/365,IF(J$19<=$C$15,(DATE(J$19,12,31)-MAX(Inputs!$C$5+1,DATE(J$19,1,1))+1)/365,0)) -> 1.0027397 | K20: =IF($C$13=1,MAX(0,MIN(DATE(K$19,12,31),$C$14)-MAX(Inputs!$C$5+1,DATE(K$19,1,1))+1)/365,IF(K$19<=$C$15,(DATE(K$19,12,31)-MAX(Inputs!$C$5+1,DATE(K$19,1,1))+1)/365,0)) -> 1 | ... AV20: =IF($C$13=1,MAX(0,MIN(DATE(AV$19,12,31),$C$14)-MAX(Inputs!$C$5+1,DATE(AV$19,1,1))+1)/365,IF(AV$19<=$C$15,(DATE(AV$19,12,31)-MAX(Inputs!$C$5+1,DATE(AV$19,1,1))+1)/365,0)) -> 0
B21: Revenue (full-year run-rate) | D21: =$C$5*(1+$C$6) -> 3901.497 | E21: =D21*(1+$C$7) -> 3983.4284 | F21: =E21*(1+$C$7) -> 4067.0804 | G21: =F21*(1+$C$7) -> 4152.4891 | H21: =G21*(1+$C$7) -> 4239.6914 | I21: =H21*(1+$C$7) -> 4328.7249 | J21: =I21*(1+$C$7) -> 4419.6281 | K21: =J21*(1+$C$7) -> 4512.4403 | L21: =K21*(1+$C$7) -> 4607.2016 | ... AV21: =AU21*(1+$C$7) -> 9735.6271
B22: EBITDA | D22: =D21*$C$8 -> 2772.0136 | E22: =E21*$C$8 -> 2830.2259 | F22: =F21*$C$8 -> 2889.6606 | G22: =G21*$C$8 -> 2950.3435 | H22: =H21*$C$8 -> 3012.3007 | I22: =I21*$C$8 -> 3075.5591 | J22: =J21*$C$8 -> 3140.1458 | K22: =K21*$C$8 -> 3206.0889 | ... AV22: =AV21*$C$8 -> 6917.163
B23: D&A | D23: =-D21*$C$9 -> -870.81413 | E23: =-E21*$C$9 -> -889.10123 | F23: =-F21*$C$9 -> -907.77235 | G23: =-G21*$C$9 -> -926.83557 | H23: =-H21*$C$9 -> -946.29912 | I23: =-I21*$C$9 -> -966.1714 | J23: =-J21*$C$9 -> -986.461 | K23: =-K21*$C$9 -> -1007.1767 | ... AV23: =-AV21*$C$9 -> -2172.992
B24: EBIT | D24: =D22+D23 -> 1901.1995 | E24: =E22+E23 -> 1941.1247 | F24: =F22+F23 -> 1981.8883 | G24: =G22+G23 -> 2023.5079 | H24: =H22+H23 -> 2066.0016 | I24: =I22+I23 -> 2109.3877 | J24: =J22+J23 -> 2153.6848 | K24: =K22+K23 -> 2198.9122 | ... AV24: =AV22+AV23 -> 4744.1711
B25: Tax rate | D25: =IF(D$19=2026,Inputs!$C$10,Inputs!$C$11) -> 0.348 | E25: =IF(E$19=2026,Inputs!$C$10,Inputs!$C$11) -> 0.258 | F25: =IF(F$19=2026,Inputs!$C$10,Inputs!$C$11) -> 0.258 | G25: =IF(G$19=2026,Inputs!$C$10,Inputs!$C$11) -> 0.258 | H25: =IF(H$19=2026,Inputs!$C$10,Inputs!$C$11) -> 0.258 | I25: =IF(I$19=2026,Inputs!$C$10,Inputs!$C$11) -> 0.258 | J25: =IF(J$19=2026,Inputs!$C$10,Inputs!$C$11) -> 0.258 | K25: =IF(K$19=2026,Inputs!$C$10,Inputs!$C$11) -> 0.258 | ... AV25: =IF(AV$19=2026,Inputs!$C$10,Inputs!$C$11) -> 0.258
B26: Tax on EBIT | D26: =-MAX(0,D24)*D25 -> -661.61742 | E26: =-MAX(0,E24)*E25 -> -500.81017 | F26: =-MAX(0,F24)*F25 -> -511.32718 | G26: =-MAX(0,G24)*G25 -> -522.06505 | H26: =-MAX(0,H24)*H25 -> -533.02842 | I26: =-MAX(0,I24)*I25 -> -544.22201 | J26: =-MAX(0,J24)*J25 -> -555.65068 | K26: =-MAX(0,K24)*K25 -> -567.31934 | ... AV26: =-MAX(0,AV24)*AV25 -> -1223.9961
B27: Capex | D27: =-D21*$C$10 -> -340.60069 | E27: =-E21*$C$10 -> -347.7533 | F27: =-F21*$C$10 -> -355.05612 | G27: =-G21*$C$10 -> -362.5123 | H27: =-H21*$C$10 -> -370.12506 | I27: =-I21*$C$10 -> -377.89769 | J27: =-J21*$C$10 -> -385.83354 | K27: =-K21*$C$10 -> -393.93604 | ... AV27: =-AV21*$C$10 -> -849.92024
B28: Lease repayments | D28: =-D21*$C$11 -> -7.0226946 | E28: =-E21*$C$11 -> -7.1701712 | F28: =-F21*$C$11 -> -7.3207448 | G28: =-G21*$C$11 -> -7.4744804 | H28: =-H21*$C$11 -> -7.6314445 | I28: =-I21*$C$11 -> -7.7917048 | J28: =-J21*$C$11 -> -7.9553306 | K28: =-K21*$C$11 -> -8.1223926 | ... AV28: =-AV21*$C$11 -> -17.524129
B29: Unlevered FCF in valuation window | D29: =(D22+D26+D27+D28)*D20 -> 888.63068 | E29: =(E22+E26+E27+E28)*E20 -> 1974.4923 | F29: =(F22+F26+F27+F28)*F20 -> 2021.4798 | G29: =(G22+G26+G27+G28)*G20 -> 2058.2917 | H29: =(H22+H26+H27+H28)*H20 -> 2101.5158 | I29: =(I22+I26+I27+I28)*I20 -> 2145.6476 | J29: =(J22+J26+J27+J28)*J20 -> 2196.7082 | K29: =(K22+K26+K27+K28)*K20 -> 2236.7111 | ... AV29: =(AV22+AV26+AV27+AV28)*AV20 -> 0
B30: Discount period (mid-period, years) | D30: =((MAX(Inputs!$C$5+1,DATE(D$19,1,1))+DATE(D$19,12,31))/2-Inputs!$C$5)/365 -> 0.25342466 | E30: =((MAX(Inputs!$C$5+1,DATE(E$19,1,1))+DATE(E$19,12,31))/2-Inputs!$C$5)/365 -> 1.0054795 | F30: =((MAX(Inputs!$C$5+1,DATE(F$19,1,1))+DATE(F$19,12,31))/2-Inputs!$C$5)/365 -> 2.0068493 | G30: =((MAX(Inputs!$C$5+1,DATE(G$19,1,1))+DATE(G$19,12,31))/2-Inputs!$C$5)/365 -> 3.0082192 | H30: =((MAX(Inputs!$C$5+1,DATE(H$19,1,1))+DATE(H$19,12,31))/2-Inputs!$C$5)/365 -> 4.0082192 | I30: =((MAX(Inputs!$C$5+1,DATE(I$19,1,1))+DATE(I$19,12,31))/2-Inputs!$C$5)/365 -> 5.0082192 | J30: =((MAX(Inputs!$C$5+1,DATE(J$19,1,1))+DATE(J$19,12,31))/2-Inputs!$C$5)/365 -> 6.009589 | K30: =((MAX(Inputs!$C$5+1,DATE(K$19,1,1))+DATE(K$19,12,31))/2-Inputs!$C$5)/365 -> 7.0109589 | ... AV30: =((MAX(Inputs!$C$5+1,DATE(AV$19,1,1))+DATE(AV$19,12,31))/2-Inputs!$C$5)/365 -> 44.035616
B31: Discount factor | D31: =1/(1+$C$12)^D30 -> 0.98416731 | E31: =1/(1+$C$12)^E30 -> 0.93864319 | F31: =1/(1+$C$12)^F30 -> 0.88127907 | G31: =1/(1+$C$12)^G30 -> 0.82742071 | H31: =1/(1+$C$12)^H30 -> 0.77692085 | I31: =1/(1+$C$12)^I30 -> 0.72950315 | J31: =1/(1+$C$12)^J30 -> 0.68492039 | K31: =1/(1+$C$12)^K30 -> 0.64306226 | ... AV31: =1/(1+$C$12)^AV30 -> 0.062465923
B32: PV of UFCF | D32: =D29*D31 -> 874.56126 | E32: =E29*E31 -> 1853.3437 | F32: =F29*F31 -> 1781.4878 | G32: =G29*G31 -> 1703.0732 | H32: =H29*H31 -> 1632.7115 | I32: =I29*I31 -> 1565.2567 | J32: =J29*J31 -> 1504.5702 | K32: =K29*K31 -> 1438.3445 | ... AV32: =AV29*AV31 -> 0
B33: Terminal-year normalised FCF (before growth) | D33: =IF(AND($C$13=0,D$19=$C$15),D22-D21*($C$17+$C$11)-MAX(0,D22-D21*$C$17)*Inputs!$C$11,0) -> 0 | E33: =IF(AND($C$13=0,E$19=$C$15),E22-E21*($C$17+$C$11)-MAX(0,E22-E21*$C$17)*Inputs!$C$11,0) -> 0 | F33: =IF(AND($C$13=0,F$19=$C$15),F22-F21*($C$17+$C$11)-MAX(0,F22-F21*$C$17)*Inputs!$C$11,0) -> 0 | G33: =IF(AND($C$13=0,G$19=$C$15),G22-G21*($C$17+$C$11)-MAX(0,G22-G21*$C$17)*Inputs!$C$11,0) -> 0 | H33: =IF(AND($C$13=0,H$19=$C$15),H22-H21*($C$17+$C$11)-MAX(0,H22-H21*$C$17)*Inputs!$C$11,0) -> 0 | I33: =IF(AND($C$13=0,I$19=$C$15),I22-I21*($C$17+$C$11)-MAX(0,I22-I21*$C$17)*Inputs!$C$11,0) -> 0 | J33: =IF(AND($C$13=0,J$19=$C$15),J22-J21*($C$17+$C$11)-MAX(0,J22-J21*$C$17)*Inputs!$C$11,0) -> 0 | K33: =IF(AND($C$13=0,K$19=$C$15),K22-K21*($C$17+$C$11)-MAX(0,K22-K21*$C$17)*Inputs!$C$11,0) -> 0 | ... AV33: =IF(AND($C$13=0,AV$19=$C$15),AV22-AV21*($C$17+$C$11)-MAX(0,AV22-AV21*$C$17)*Inputs!$C$11,0) -> 0
B34: PV of terminal value | D34: =D33*(1+$C$16)/($C$12-$C$16)*D31 -> 0 | E34: =E33*(1+$C$16)/($C$12-$C$16)*E31 -> 0 | F34: =F33*(1+$C$16)/($C$12-$C$16)*F31 -> 0 | G34: =G33*(1+$C$16)/($C$12-$C$16)*G31 -> 0 | H34: =H33*(1+$C$16)/($C$12-$C$16)*H31 -> 0 | I34: =I33*(1+$C$16)/($C$12-$C$16)*I31 -> 0 | J34: =J33*(1+$C$16)/($C$12-$C$16)*J31 -> 0 | K34: =K33*(1+$C$16)/($C$12-$C$16)*K31 -> 0 | ... AV34: =AV33*(1+$C$16)/($C$12-$C$16)*AV31 -> 0
B36: PV of explicit / concession-life cash flows | C36: =SUM($D$32:$AV$32) -> 16324.916
B37: PV of terminal value | C37: =SUM($D$34:$AV$34) -> 0
B38: ENTERPRISE VALUE — ASF (100%) | C38: =C36+C37 -> 16324.916
B39: Terminal value as % of block EV | C39: =IF(C38=0,0,C37/C38) -> 0
B40: Implied EV / FY2026E EBITDA | C40: =IF(D22=0,0,C38/D22) -> 5.8891906
B41: Terminal FCF base (for sensitivity) | C41: =SUM($D$33:$AV$33) -> 0
B42: Terminal discount period (for sensitivity) | C42: =SUMPRODUCT(($D$19:$AV$19=$C$15)*$D$30:$AV$30) -> 0
B43: Check: WACC > g and no cash flow after concession end | C43: =IF(AND($C$12>$C$16,SUMPRODUCT(($D$19:$AV$19>YEAR($C$14))*($C$13=1)*ABS($D$29:$AV$29))=0),"OK","REVISAR") -> OK
B46: Escota
...

Sheet Airports
B2: Airports — airports by ownership regime
B4: Gatwick + Edinburgh (freehold, 50.01%)
B5: Base revenue FY2025 (EUR m) | C5: 1740 | D5: Revenue FY2025: Gatwick 1,321 + Edinburgh 419 (Note I.23.5). ASSUMPTION: VINCI Airports segment margin 63.4%, D&A 11.7%, capex 13.3% (375 operating + 263 growth), leases 0.5% applied. Explicit to 2035 (covers Gatwick northern-runway capex cycle), then Gordon with g 2.0% and normalised capex 6%. Owned outright → a terminal value is legitimate. Consolidated at 100%; the 49.99% third-party share is deducted in the SOTP bridge on implied equity value. H1 2026 VINCI Airports revenue +1.8% → 2.0% for FY2026.
B6: Revenue growth FY2026 | C6: 0.02
B7: Revenue growth FY2027+ | C7: 0.035
B8: EBITDA margin (CFO before tax & financing / revenue) | C8: 0.6343
B9: D&A % revenue | C9: 0.1172
B10: Capex % revenue (operating + growth investments) | C10: 0.133
B11: Lease repayments % revenue | C11: 0.0048
B12: Discount rate (post-tax WACC) | C12: 0.075
B13: Type: 1 = finite concession (TV = 0) · 0 = going concern | C13: 0
B14: Concession end date (finite only) | C14: 46387
B15: Last explicit year (going concern only) | C15: 2035
B16: Terminal growth g (going concern only) | C16: 0.02
B17: Terminal capex % revenue (going concern only) | C17: 0.06
B19: Fiscal year | D19: 2026 | E19: 2027 | F19: 2028 | G19: 2029 | H19: 2030 | I19: 2031 | J19: 2032 | K19: 2033 | L19: 2034 | M19: 2035 | N19: 2036 | O19: 2037 | P19: 2038 | Q19: 2039 | R19: 2040 | S19: 2041 | T19: 2042 | U19: 2043 | V19: 2044 | W19: 2045 | X19: 2046 | Y19: 2047 | Z19: 2048 | AA19: 2049 | AB19: 2050 | AC19: 2051 | AD19: 2052 | AE19: 2053 | AF19: 2054 | AG19: 2055 | AH19: 2056 | AI19: 2057 | AJ19: 2058 | AK19: 2059 | AL19: 2060 | AM19: 2061 | AN19: 2062 | AO19: 2063 | AP19: 2064 | AQ19: 2065 | AR19: 2066 | AS19: 2067 | AT19: 2068 | AU19: 2069 | AV19: 2070
B20: Fraction of year in valuation (after val. date / before concession end) | D20: =IF($C$13=1,MAX(0,MIN(DATE(D$19,12,31),$C$14)-MAX(Inputs!$C$5+1,DATE(D$19,1,1))+1)/365,IF(D$19<=$C$15,(DATE(D$19,12,31)-MAX(Inputs!$C$5+1,DATE(D$19,1,1))+1)/365,0)) -> 0.50410959 | E20: =IF($C$13=1,MAX(0,MIN(DATE(E$19,12,31),$C$14)-MAX(Inputs!$C$5+1,DATE(E$19,1,1))+1)/365,IF(E$19<=$C$15,(DATE(E$19,12,31)-MAX(Inputs!$C$5+1,DATE(E$19,1,1))+1)/365,0)) -> 1 | F20: =IF($C$13=1,MAX(0,MIN(DATE(F$19,12,31),$C$14)-MAX(Inputs!$C$5+1,DATE(F$19,1,1))+1)/365,IF(F$19<=$C$15,(DATE(F$19,12,31)-MAX(Inputs!$C$5+1,DATE(F$19,1,1))+1)/365,0)) -> 1.0027397 | G20: =IF($C$13=1,MAX(0,MIN(DATE(G$19,12,31),$C$14)-MAX(Inputs!$C$5+1,DATE(G$19,1,1))+1)/365,IF(G$19<=$C$15,(DATE(G$19,12,31)-MAX(Inputs!$C$5+1,DATE(G$19,1,1))+1)/365,0)) -> 1 | H20: =IF($C$13=1,MAX(0,MIN(DATE(H$19,12,31),$C$14)-MAX(Inputs!$C$5+1,DATE(H$19,1,1))+1)/365,IF(H$19<=$C$15,(DATE(H$19,12,31)-MAX(Inputs!$C$5+1,DATE(H$19,1,1))+1)/365,0)) -> 1 | I20: =IF($C$13=1,MAX(0,MIN(DATE(I$19,12,31),$C$14)-MAX(Inputs!$C$5+1,DATE(I$19,1,1))+1)/365,IF(I$19<=$C$15,(DATE(I$19,12,31)-MAX(Inputs!$C$5+1,DATE(I$19,1,1))+1)/365,0)) -> 1 | J20: =IF($C$13=1,MAX(0,MIN(DATE(J$19,12,31),$C$14)-MAX(Inputs!$C$5+1,DATE(J$19,1,1))+1)/365,IF(J$19<=$C$15,(DATE(J$19,12,31)-MAX(Inputs!$C$5+1,DATE(J$19,1,1))+1)/365,0)) -> 1.0027397 | K20: =IF($C$13=1,MAX(0,MIN(DATE(K$19,12,31),$C$14)-MAX(Inputs!$C$5+1,DATE(K$19,1,1))+1)/365,IF(K$19<=$C$15,(DATE(K$19,12,31)-MAX(Inputs!$C$5+1,DATE(K$19,1,1))+1)/365,0)) -> 1 | ... AV20: =IF($C$13=1,MAX(0,MIN(DATE(AV$19,12,31),$C$14)-MAX(Inputs!$C$5+1,DATE(AV$19,1,1))+1)/365,IF(AV$19<=$C$15,(DATE(AV$19,12,31)-MAX(Inputs!$C$5+1,DATE(AV$19,1,1))+1)/365,0)) -> 0
B21: Revenue (full-year run-rate) | D21: =$C$5*(1+$C$6) -> 1774.8 | E21: =D21*(1+$C$7) -> 1836.918 | F21: =E21*(1+$C$7) -> 1901.2101 | G21: =F21*(1+$C$7) -> 1967.7525 | H21: =G21*(1+$C$7) -> 2036.6238 | I21: =H21*(1+$C$7) -> 2107.9057 | J21: =I21*(1+$C$7) -> 2181.6824 | K21: =J21*(1+$C$7) -> 2258.0412 | L21: =K21*(1+$C$7) -> 2337.0727 | ... AV21: =AU21*(1+$C$7) -> 8063.5227
B22: EBITDA | D22: =D21*$C$8 -> 1125.7556 | E22: =E21*$C$8 -> 1165.1571 | F22: =F21*$C$8 -> 1205.9376 | G22: =G21*$C$8 -> 1248.1454 | H22: =H21*$C$8 -> 1291.8305 | I22: =I21*$C$8 -> 1337.0446 | J22: =J21*$C$8 -> 1383.8411 | K22: =K21*$C$8 -> 1432.2756 | ... AV22: =AV21*$C$8 -> 5114.6924
B23: D&A | D23: =-D21*$C$9 -> -208.00656 | E23: =-E21*$C$9 -> -215.28679 | F23: =-F21*$C$9 -> -222.82183 | G23: =-G21*$C$9 -> -230.62059 | H23: =-H21*$C$9 -> -238.69231 | I23: =-I21*$C$9 -> -247.04654 | J23: =-J21*$C$9 -> -255.69317 | K23: =-K21*$C$9 -> -264.64243 | ... AV23: =-AV21*$C$9 -> -945.04486
B24: EBIT | D24: =D22+D23 -> 917.74908 | E24: =E22+E23 -> 949.8703 | F24: =F22+F23 -> 983.11576 | G24: =G22+G23 -> 1017.5248 | H24: =H22+H23 -> 1053.1382 | I24: =I22+I23 -> 1089.998 | J24: =J22+J23 -> 1128.1479 | K24: =K22+K23 -> 1167.6331 | ... AV24: =AV22+AV23 -> 4169.6476
B25: Tax rate | D25: =IF(D$19=2026,Inputs!$C$10,Inputs!$C$11) -> 0.348 | E25: =IF(E$19=2026,Inputs!$C$10,Inputs!$C$11) -> 0.258 | F25: =IF(F$19=2026,Inputs!$C$10,Inputs!$C$11) -> 0.258 | G25: =IF(G$19=2026,Inputs!$C$10,Inputs!$C$11) -> 0.258 | H25: =IF(H$19=2026,Inputs!$C$10,Inputs!$C$11) -> 0.258 | I25: =IF(I$19=2026,Inputs!$C$10,Inputs!$C$11) -> 0.258 | J25: =IF(J$19=2026,Inputs!$C$10,Inputs!$C$11) -> 0.258 | K25: =IF(K$19=2026,Inputs!$C$10,Inputs!$C$11) -> 0.258 | ... AV25: =IF(AV$19=2026,Inputs!$C$10,Inputs!$C$11) -> 0.258
B26: Tax on EBIT | D26: =-MAX(0,D24)*D25 -> -319.37668 | E26: =-MAX(0,E24)*E25 -> -245.06654 | F26: =-MAX(0,F24)*F25 -> -253.64387 | G26: =-MAX(0,G24)*G25 -> -262.5214 | H26: =-MAX(0,H24)*H25 -> -271.70965 | I26: =-MAX(0,I24)*I25 -> -281.21949 | J26: =-MAX(0,J24)*J25 -> -291.06217 | K26: =-MAX(0,K24)*K25 -> -301.24935 | ... AV26: =-MAX(0,AV24)*AV25 -> -1075.7691
B27: Capex | D27: =-D21*$C$10 -> -236.0484 | E27: =-E21*$C$10 -> -244.31009 | F27: =-F21*$C$10 -> -252.86095 | G27: =-G21*$C$10 -> -261.71108 | H27: =-H21*$C$10 -> -270.87097 | I27: =-I21*$C$10 -> -280.35145 | J27: =-J21*$C$10 -> -290.16375 | K27: =-K21*$C$10 -> -300.31948 | ... AV27: =-AV21*$C$10 -> -1072.4485
B28: Lease repayments | D28: =-D21*$C$11 -> -8.51904 | E28: =-E21*$C$11 -> -8.8172064 | F28: =-F21*$C$11 -> -9.1258086 | G28: =-G21*$C$11 -> -9.4452119 | H28: =-H21*$C$11 -> -9.7757943 | I28: =-I21*$C$11 -> -10.117947 | J28: =-J21*$C$11 -> -10.472075 | K28: =-K21*$C$11 -> -10.838598 | ... AV28: =-AV21*$C$11 -> -38.704909
B29: Unlevered FCF in valuation window | D29: =(D22+D26+D27+D28)*D20 -> 283.21457 | E29: =(E22+E26+E27+E28)*E20 -> 666.96325 | F29: =(F22+F26+F27+F28)*F20 -> 692.19822 | G29: =(G22+G26+G27+G28)*G20 -> 714.46771 | H29: =(H22+H26+H27+H28)*H20 -> 739.47408 | I29: =(I22+I26+I27+I28)*I20 -> 765.35567 | J29: =(J22+J26+J27+J28)*J20 -> 794.31337 | K29: =(K22+K26+K27+K28)*K20 -> 819.86813 | ... AV29: =(AV22+AV26+AV27+AV28)*AV20 -> 0
B30: Discount period (mid-period, years) | D30: =((MAX(Inputs!$C$5+1,DATE(D$19,1,1))+DATE(D$19,12,31))/2-Inputs!$C$5)/365 -> 0.25342466 | E30: =((MAX(Inputs!$C$5+1,DATE(E$19,1,1))+DATE(E$19,12,31))/2-Inputs!$C$5)/365 -> 1.0054795 | F30: =((MAX(Inputs!$C$5+1,DATE(F$19,1,1))+DATE(F$19,12,31))/2-Inputs!$C$5)/365 -> 2.0068493 | G30: =((MAX(Inputs!$C$5+1,DATE(G$19,1,1))+DATE(G$19,12,31))/2-Inputs!$C$5)/365 -> 3.0082192 | H30: =((MAX(Inputs!$C$5+1,DATE(H$19,1,1))+DATE(H$19,12,31))/2-Inputs!$C$5)/365 -> 4.0082192 | I30: =((MAX(Inputs!$C$5+1,DATE(I$19,1,1))+DATE(I$19,12,31))/2-Inputs!$C$5)/365 -> 5.0082192 | J30: =((MAX(Inputs!$C$5+1,DATE(J$19,1,1))+DATE(J$19,12,31))/2-Inputs!$C$5)/365 -> 6.009589 | K30: =((MAX(Inputs!$C$5+1,DATE(K$19,1,1))+DATE(K$19,12,31))/2-Inputs!$C$5)/365 -> 7.0109589 | ... AV30: =((MAX(Inputs!$C$5+1,DATE(AV$19,1,1))+DATE(AV$19,12,31))/2-Inputs!$C$5)/365 -> 44.035616
B31: Discount factor | D31: =1/(1+$C$12)^D30 -> 0.98183909 | E31: =1/(1+$C$12)^E30 -> 0.929864 | F31: =1/(1+$C$12)^F30 -> 0.86490408 | G31: =1/(1+$C$12)^G30 -> 0.80448223 | H31: =1/(1+$C$12)^H30 -> 0.74835556 | I31: =1/(1+$C$12)^I30 -> 0.69614471 | J31: =1/(1+$C$12)^J30 -> 0.64751232 | K31: =1/(1+$C$12)^K30 -> 0.60227737 | ... AV31: =1/(1+$C$12)^AV30 -> 0.041391286
B32: PV of UFCF | D32: =D29*D31 -> 278.07114 | E32: =E29*E31 -> 620.18512 | F32: =F29*F31 -> 598.68506 | G32: =G29*G31 -> 574.77657 | H32: =H29*H31 -> 553.38954 | I32: =I29*I31 -> 532.7983 | J32: =J29*J31 -> 514.3277 | K32: =K29*K31 -> 493.78802 | ... AV32: =AV29*AV31 -> 0
B33: Terminal-year normalised FCF (before growth) | D33: =IF(AND($C$13=0,D$19=$C$15),D22-D21*($C$17+$C$11)-MAX(0,D22-D21*$C$17)*Inputs!$C$11,0) -> 0 | E33: =IF(AND($C$13=0,E$19=$C$15),E22-E21*($C$17+$C$11)-MAX(0,E22-E21*$C$17)*Inputs!$C$11,0) -> 0 | F33: =IF(AND($C$13=0,F$19=$C$15),F22-F21*($C$17+$C$11)-MAX(0,F22-F21*$C$17)*Inputs!$C$11,0) -> 0 | G33: =IF(AND($C$13=0,G$19=$C$15),G22-G21*($C$17+$C$11)-MAX(0,G22-G21*$C$17)*Inputs!$C$11,0) -> 0 | H33: =IF(AND($C$13=0,H$19=$C$15),H22-H21*($C$17+$C$11)-MAX(0,H22-H21*$C$17)*Inputs!$C$11,0) -> 0 | I33: =IF(AND($C$13=0,I$19=$C$15),I22-I21*($C$17+$C$11)-MAX(0,I22-I21*$C$17)*Inputs!$C$11,0) -> 0 | J33: =IF(AND($C$13=0,J$19=$C$15),J22-J21*($C$17+$C$11)-MAX(0,J22-J21*$C$17)*Inputs!$C$11,0) -> 0 | K33: =IF(AND($C$13=0,K$19=$C$15),K22-K21*($C$17+$C$11)-MAX(0,K22-K21*$C$17)*Inputs!$C$11,0) -> 0 | ... AV33: =IF(AND($C$13=0,AV$19=$C$15),AV22-AV21*($C$17+$C$11)-MAX(0,AV22-AV21*$C$17)*Inputs!$C$11,0) -> 0
B34: PV of terminal value | D34: =D33*(1+$C$16)/($C$12-$C$16)*D31 -> 0 | E34: =E33*(1+$C$16)/($C$12-$C$16)*E31 -> 0 | F34: =F33*(1+$C$16)/($C$12-$C$16)*F31 -> 0 | G34: =G33*(1+$C$16)/($C$12-$C$16)*G31 -> 0 | H34: =H33*(1+$C$16)/($C$12-$C$16)*H31 -> 0 | I34: =I33*(1+$C$16)/($C$12-$C$16)*I31 -> 0 | J34: =J33*(1+$C$16)/($C$12-$C$16)*J31 -> 0 | K34: =K33*(1+$C$16)/($C$12-$C$16)*K31 -> 0 | ... AV34: =AV33*(1+$C$16)/($C$12-$C$16)*AV31 -> 0
B36: PV of explicit / concession-life cash flows | C36: =SUM($D$32:$AV$32) -> 5099.1606
B37: PV of terminal value | C37: =SUM($D$34:$AV$34) -> 9850.3729
B38: ENTERPRISE VALUE — Gatwick + Edinburgh (freehold, 50.01%) (100%) | C38: =C36+C37 -> 14949.534
B39: Terminal value as % of block EV | C39: =IF(C38=0,0,C37/C38) -> 0.65890838
B40: Implied EV / FY2026E EBITDA | C40: =IF(D22=0,0,C38/D22) -> 13.279555
B41: Terminal FCF base (for sensitivity) | C41: =SUM($D$33:$AV$33) -> 1019.144
B42: Terminal discount period (for sensitivity) | C42: =SUMPRODUCT(($D$19:$AV$19=$C$15)*$D$30:$AV$30) -> 9.0109589
B43: Check: WACC > g and no cash flow after concession end | C43: =IF(AND($C$12>$C$16,SUMPRODUCT(($D$19:$AV$19>YEAR($C$14))*($C$13=1)*ABS($D$29:$AV$29))=0),"OK","REVISAR") -> OK
B46: OMA Mexico (to 2048, 29.99%)
...

Sheet Other_Concessions
B2: Other Concessions — VINCI Highways, Railways, Stadium
B4: Other concessions (VINCI Highways etc.)
B5: Base revenue FY2025 (EUR m) | C5: 690 | D5: FY2025 segment (Note C.1.2): revenue 690, EBITDA 344, D&A 102, operating capex 32, leases 3 (growth investments +10 ignored). Contracts: Entrevias 2047, Via Cristais 2055, Vía Sumapaz 2046, Lima Expresa 2049, Northwest Parkway 2106, Gefyra 2039, Confederation Bridge 2032. ASSUMPTION: single end date 2050. FY2026 growth 5.3% = Vinci impairment-test average for Highways; 4.0% thereafter. WACC 8.0% (LatAm/US mix).
B6: Revenue growth FY2026 | C6: 0.053
B7: Revenue growth FY2027+ | C7: 0.04
B8: EBITDA margin (CFO before tax & financing / revenue) | C8: 0.4986
B9: D&A % revenue | C9: 0.1478
B10: Capex % revenue (operating + growth investments) | C10: 0.0464
B11: Lease repayments % revenue | C11: 0.0043
B12: Discount rate (post-tax WACC) | C12: 0.08
B13: Type: 1 = finite concession (TV = 0) · 0 = going concern | C13: 1
B14: Concession end date (finite only) | C14: 55153
B15: Last explicit year (going concern only) | C15: 0
B16: Terminal growth g (going concern only) | C16: 0
B17: Terminal capex % revenue (going concern only) | C17: 0
B19: Fiscal year | D19: 2026 | E19: 2027 | F19: 2028 | G19: 2029 | H19: 2030 | I19: 2031 | J19: 2032 | K19: 2033 | L19: 2034 | M19: 2035 | N19: 2036 | O19: 2037 | P19: 2038 | Q19: 2039 | R19: 2040 | S19: 2041 | T19: 2042 | U19: 2043 | V19: 2044 | W19: 2045 | X19: 2046 | Y19: 2047 | Z19: 2048 | AA19: 2049 | AB19: 2050 | AC19: 2051 | AD19: 2052 | AE19: 2053 | AF19: 2054 | AG19: 2055 | AH19: 2056 | AI19: 2057 | AJ19: 2058 | AK19: 2059 | AL19: 2060 | AM19: 2061 | AN19: 2062 | AO19: 2063 | AP19: 2064 | AQ19: 2065 | AR19: 2066 | AS19: 2067 | AT19: 2068 | AU19: 2069 | AV19: 2070
B20: Fraction of year in valuation (after val. date / before concession end) | D20: =IF($C$13=1,MAX(0,MIN(DATE(D$19,12,31),$C$14)-MAX(Inputs!$C$5+1,DATE(D$19,1,1))+1)/365,IF(D$19<=$C$15,(DATE(D$19,12,31)-MAX(Inputs!$C$5+1,DATE(D$19,1,1))+1)/365,0)) -> 0.50410959 | E20: =IF($C$13=1,MAX(0,MIN(DATE(E$19,12,31),$C$14)-MAX(Inputs!$C$5+1,DATE(E$19,1,1))+1)/365,IF(E$19<=$C$15,(DATE(E$19,12,31)-MAX(Inputs!$C$5+1,DATE(E$19,1,1))+1)/365,0)) -> 1 | F20: =IF($C$13=1,MAX(0,MIN(DATE(F$19,12,31),$C$14)-MAX(Inputs!$C$5+1,DATE(F$19,1,1))+1)/365,IF(F$19<=$C$15,(DATE(F$19,12,31)-MAX(Inputs!$C$5+1,DATE(F$19,1,1))+1)/365,0)) -> 1.0027397 | G20: =IF($C$13=1,MAX(0,MIN(DATE(G$19,12,31),$C$14)-MAX(Inputs!$C$5+1,DATE(G$19,1,1))+1)/365,IF(G$19<=$C$15,(DATE(G$19,12,31)-MAX(Inputs!$C$5+1,DATE(G$19,1,1))+1)/365,0)) -> 1 | H20: =IF($C$13=1,MAX(0,MIN(DATE(H$19,12,31),$C$14)-MAX(Inputs!$C$5+1,DATE(H$19,1,1))+1)/365,IF(H$19<=$C$15,(DATE(H$19,12,31)-MAX(Inputs!$C$5+1,DATE(H$19,1,1))+1)/365,0)) -> 1 | I20: =IF($C$13=1,MAX(0,MIN(DATE(I$19,12,31),$C$14)-MAX(Inputs!$C$5+1,DATE(I$19,1,1))+1)/365,IF(I$19<=$C$15,(DATE(I$19,12,31)-MAX(Inputs!$C$5+1,DATE(I$19,1,1))+1)/365,0)) -> 1 | J20: =IF($C$13=1,MAX(0,MIN(DATE(J$19,12,31),$C$14)-MAX(Inputs!$C$5+1,DATE(J$19,1,1))+1)/365,IF(J$19<=$C$15,(DATE(J$19,12,31)-MAX(Inputs!$C$5+1,DATE(J$19,1,1))+1)/365,0)) -> 1.0027397 | K20: =IF($C$13=1,MAX(0,MIN(DATE(K$19,12,31),$C$14)-MAX(Inputs!$C$5+1,DATE(K$19,1,1))+1)/365,IF(K$19<=$C$15,(DATE(K$19,12,31)-MAX(Inputs!$C$5+1,DATE(K$19,1,1))+1)/365,0)) -> 1 | ... AV20: =IF($C$13=1,MAX(0,MIN(DATE(AV$19,12,31),$C$14)-MAX(Inputs!$C$5+1,DATE(AV$19,1,1))+1)/365,IF(AV$19<=$C$15,(DATE(AV$19,12,31)-MAX(Inputs!$C$5+1,DATE(AV$19,1,1))+1)/365,0)) -> 0
B21: Revenue (full-year run-rate) | D21: =$C$5*(1+$C$6) -> 726.57 | E21: =D21*(1+$C$7) -> 755.6328 | F21: =E21*(1+$C$7) -> 785.85811 | G21: =F21*(1+$C$7) -> 817.29244 | H21: =G21*(1+$C$7) -> 849.98413 | I21: =H21*(1+$C$7) -> 883.9835 | J21: =I21*(1+$C$7) -> 919.34284 | K21: =J21*(1+$C$7) -> 956.11655 | L21: =K21*(1+$C$7) -> 994.36121 | ... AV21: =AU21*(1+$C$7) -> 4080.7914
B22: EBITDA | D22: =D21*$C$8 -> 362.2678 | E22: =E21*$C$8 -> 376.75851 | F22: =F21*$C$8 -> 391.82885 | G22: =G21*$C$8 -> 407.50201 | H22: =H21*$C$8 -> 423.80209 | I22: =I21*$C$8 -> 440.75417 | J22: =J21*$C$8 -> 458.38434 | K22: =K21*$C$8 -> 476.71971 | ... AV22: =AV21*$C$8 -> 2034.6826
B23: D&A | D23: =-D21*$C$9 -> -107.38705 | E23: =-E21*$C$9 -> -111.68253 | F23: =-F21*$C$9 -> -116.14983 | G23: =-G21*$C$9 -> -120.79582 | H23: =-H21*$C$9 -> -125.62765 | I23: =-I21*$C$9 -> -130.65276 | J23: =-J21*$C$9 -> -135.87887 | K23: =-K21*$C$9 -> -141.31403 | ... AV23: =-AV21*$C$9 -> -603.14096
B24: EBIT | D24: =D22+D23 -> 254.88076 | E24: =E22+E23 -> 265.07599 | F24: =F22+F23 -> 275.67903 | G24: =G22+G23 -> 286.70619 | H24: =H22+H23 -> 298.17443 | I24: =I22+I23 -> 310.10141 | J24: =J22+J23 -> 322.50547 | K24: =K22+K23 -> 335.40569 | ... AV24: =AV22+AV23 -> 1431.5416
B25: Tax rate | D25: =IF(D$19=2026,Inputs!$C$10,Inputs!$C$11) -> 0.348 | E25: =IF(E$19=2026,Inputs!$C$10,Inputs!$C$11) -> 0.258 | F25: =IF(F$19=2026,Inputs!$C$10,Inputs!$C$11) -> 0.258 | G25: =IF(G$19=2026,Inputs!$C$10,Inputs!$C$11) -> 0.258 | H25: =IF(H$19=2026,Inputs!$C$10,Inputs!$C$11) -> 0.258 | I25: =IF(I$19=2026,Inputs!$C$10,Inputs!$C$11) -> 0.258 | J25: =IF(J$19=2026,Inputs!$C$10,Inputs!$C$11) -> 0.258 | K25: =IF(K$19=2026,Inputs!$C$10,Inputs!$C$11) -> 0.258 | ... AV25: =IF(AV$19=2026,Inputs!$C$10,Inputs!$C$11) -> 0.258
B26: Tax on EBIT | D26: =-MAX(0,D24)*D25 -> -88.698503 | E26: =-MAX(0,E24)*E25 -> -68.389604 | F26: =-MAX(0,F24)*F25 -> -71.125189 | G26: =-MAX(0,G24)*G25 -> -73.970196 | H26: =-MAX(0,H24)*H25 -> -76.929004 | I26: =-MAX(0,I24)*I25 -> -80.006164 | J26: =-MAX(0,J24)*J25 -> -83.206411 | K26: =-MAX(0,K24)*K25 -> -86.534667 | ... AV26: =-MAX(0,AV24)*AV25 -> -369.33774
B27: Capex | D27: =-D21*$C$10 -> -33.712848 | E27: =-E21*$C$10 -> -35.061362 | F27: =-F21*$C$10 -> -36.463816 | G27: =-G21*$C$10 -> -37.922369 | H27: =-H21*$C$10 -> -39.439264 | I27: =-I21*$C$10 -> -41.016834 | J27: =-J21*$C$10 -> -42.657508 | K27: =-K21*$C$10 -> -44.363808 | ... AV27: =-AV21*$C$10 -> -189.34872
B28: Lease repayments | D28: =-D21*$C$11 -> -3.124251 | E28: =-E21*$C$11 -> -3.249221 | F28: =-F21*$C$11 -> -3.3791899 | G28: =-G21*$C$11 -> -3.5143575 | H28: =-H21*$C$11 -> -3.6549318 | I28: =-I21*$C$11 -> -3.801129 | J28: =-J21*$C$11 -> -3.9531742 | K28: =-K21*$C$11 -> -4.1113012 | ... AV28: =-AV21*$C$11 -> -17.547403
B29: Unlevered FCF in valuation window | D29: =(D22+D26+D27+D28)*D20 -> 119.33897 | E29: =(E22+E26+E27+E28)*E20 -> 270.05833 | F29: =(F22+F26+F27+F28)*F20 -> 281.63014 | G29: =(G22+G26+G27+G28)*G20 -> 292.09509 | H29: =(H22+H26+H27+H28)*H20 -> 303.77889 | I29: =(I22+I26+I27+I28)*I20 -> 315.93005 | J29: =(J22+J26+J27+J28)*J20 -> 329.46743 | K29: =(K22+K26+K27+K28)*K20 -> 341.70994 | ... AV29: =(AV22+AV26+AV27+AV28)*AV20 -> 0
B30: Discount period (mid-period, years) | D30: =((MAX(Inputs!$C$5+1,DATE(D$19,1,1))+DATE(D$19,12,31))/2-Inputs!$C$5)/365 -> 0.25342466 | E30: =((MAX(Inputs!$C$5+1,DATE(E$19,1,1))+DATE(E$19,12,31))/2-Inputs!$C$5)/365 -> 1.0054795 | F30: =((MAX(Inputs!$C$5+1,DATE(F$19,1,1))+DATE(F$19,12,31))/2-Inputs!$C$5)/365 -> 2.0068493 | G30: =((MAX(Inputs!$C$5+1,DATE(G$19,1,1))+DATE(G$19,12,31))/2-Inputs!$C$5)/365 -> 3.0082192 | H30: =((MAX(Inputs!$C$5+1,DATE(H$19,1,1))+DATE(H$19,12,31))/2-Inputs!$C$5)/365 -> 4.0082192 | I30: =((MAX(Inputs!$C$5+1,DATE(I$19,1,1))+DATE(I$19,12,31))/2-Inputs!$C$5)/365 -> 5.0082192 | J30: =((MAX(Inputs!$C$5+1,DATE(J$19,1,1))+DATE(J$19,12,31))/2-Inputs!$C$5)/365 -> 6.009589 | K30: =((MAX(Inputs!$C$5+1,DATE(K$19,1,1))+DATE(K$19,12,31))/2-Inputs!$C$5)/365 -> 7.0109589 | ... AV30: =((MAX(Inputs!$C$5+1,DATE(AV$19,1,1))+DATE(AV$19,12,31))/2-Inputs!$C$5)/365 -> 44.035616
B31: Discount factor | D31: =1/(1+$C$12)^D30 -> 0.98068514 | E31: =1/(1+$C$12)^E30 -> 0.92553554 | F31: =1/(1+$C$12)^F30 -> 0.85688701 | G31: =1/(1+$C$12)^G30 -> 0.79333026 | H31: =1/(1+$C$12)^H30 -> 0.73456505 | I31: =1/(1+$C$12)^I30 -> 0.68015283 | J31: =1/(1+$C$12)^J30 -> 0.62970474 | K31: =1/(1+$C$12)^K30 -> 0.58299848 | ... AV31: =1/(1+$C$12)^AV30 -> 0.033741495
B32: PV of UFCF | D32: =D29*D31 -> 117.03396 | E32: =E29*E31 -> 249.94858 | F32: =F29*F31 -> 241.32521 | G32: =G29*G31 -> 231.72787 | H32: =H29*H31 -> 223.14536 | I32: =I29*I31 -> 214.88071 | J32: =J29*J31 -> 207.4672 | K32: =K29*K31 -> 199.21637 | ... AV32: =AV29*AV31 -> 0
B33: Terminal-year normalised FCF (before growth) | D33: =IF(AND($C$13=0,D$19=$C$15),D22-D21*($C$17+$C$11)-MAX(0,D22-D21*$C$17)*Inputs!$C$11,0) -> 0 | E33: =IF(AND($C$13=0,E$19=$C$15),E22-E21*($C$17+$C$11)-MAX(0,E22-E21*$C$17)*Inputs!$C$11,0) -> 0 | F33: =IF(AND($C$13=0,F$19=$C$15),F22-F21*($C$17+$C$11)-MAX(0,F22-F21*$C$17)*Inputs!$C$11,0) -> 0 | G33: =IF(AND($C$13=0,G$19=$C$15),G22-G21*($C$17+$C$11)-MAX(0,G22-G21*$C$17)*Inputs!$C$11,0) -> 0 | H33: =IF(AND($C$13=0,H$19=$C$15),H22-H21*($C$17+$C$11)-MAX(0,H22-H21*$C$17)*Inputs!$C$11,0) -> 0 | I33: =IF(AND($C$13=0,I$19=$C$15),I22-I21*($C$17+$C$11)-MAX(0,I22-I21*$C$17)*Inputs!$C$11,0) -> 0 | J33: =IF(AND($C$13=0,J$19=$C$15),J22-J21*($C$17+$C$11)-MAX(0,J22-J21*$C$17)*Inputs!$C$11,0) -> 0 | K33: =IF(AND($C$13=0,K$19=$C$15),K22-K21*($C$17+$C$11)-MAX(0,K22-K21*$C$17)*Inputs!$C$11,0) -> 0 | ... AV33: =IF(AND($C$13=0,AV$19=$C$15),AV22-AV21*($C$17+$C$11)-MAX(0,AV22-AV21*$C$17)*Inputs!$C$11,0) -> 0
B34: PV of terminal value | D34: =D33*(1+$C$16)/($C$12-$C$16)*D31 -> 0 | E34: =E33*(1+$C$16)/($C$12-$C$16)*E31 -> 0 | F34: =F33*(1+$C$16)/($C$12-$C$16)*F31 -> 0 | G34: =G33*(1+$C$16)/($C$12-$C$16)*G31 -> 0 | H34: =H33*(1+$C$16)/($C$12-$C$16)*H31 -> 0 | I34: =I33*(1+$C$16)/($C$12-$C$16)*I31 -> 0 | J34: =J33*(1+$C$16)/($C$12-$C$16)*J31 -> 0 | K34: =K33*(1+$C$16)/($C$12-$C$16)*K31 -> 0 | ... AV34: =AV33*(1+$C$16)/($C$12-$C$16)*AV31 -> 0
B36: PV of explicit / concession-life cash flows | C36: =SUM($D$32:$AV$32) -> 4138.1812
B37: PV of terminal value | C37: =SUM($D$34:$AV$34) -> 0
B38: ENTERPRISE VALUE — Other concessions (VINCI Highways etc.) (100%) | C38: =C36+C37 -> 4138.1812
B39: Terminal value as % of block EV | C39: =IF(C38=0,0,C37/C38) -> 0
B40: Implied EV / FY2026E EBITDA | C40: =IF(D22=0,0,C38/D22) -> 11.422989
B41: Terminal FCF base (for sensitivity) | C41: =SUM($D$33:$AV$33) -> 0
B42: Terminal discount period (for sensitivity) | C42: =SUMPRODUCT(($D$19:$AV$19=$C$15)*$D$30:$AV$30) -> 0
B43: Check: WACC > g and no cash flow after concession end | C43: =IF(AND($C$12>$C$16,SUMPRODUCT(($D$19:$AV$19>YEAR($C$14))*($C$13=1)*ABS($D$29:$AV$29))=0),"OK","REVISAR") -> OK

Sheet Energy_Construction
B2: Energy Construction — going-concern businesses (5-year DCF + Gordon TV)
B4: VINCI Energies
B5: Base revenue FY2025 (EUR m) | C5: 21608 | D5: FY2025 segment: revenue 21,608, EBITDA 2,019, D&A 621, capex 281, leases 446. Guidance 2026: Energy Solutions mid-to-high single-digit growth with margin improvement (H1 2026: +6.8%). Margin held flat (conservative vs guidance). TV capex 1.4% ≈ D&A net of lease-related amortisation. No working-capital inflow capitalised (negative NWC is not a perpetual source of cash).
B6: Revenue growth FY2026 | C6: 0.065
B7: Revenue growth FY2027+ | C7: 0.05
B8: EBITDA margin (CFO before tax & financing / revenue) | C8: 0.0934
B9: D&A % revenue | C9: 0.0287
B10: Capex % revenue (operating + growth investments) | C10: 0.013
B11: Lease repayments % revenue | C11: 0.0206
B12: Discount rate (post-tax WACC) | C12: 0.075
B13: Type: 1 = finite concession (TV = 0) · 0 = going concern | C13: 0
B14: Concession end date (finite only) | C14: 46387
B15: Last explicit year (going concern only) | C15: 2030
B16: Terminal growth g (going concern only) | C16: 0.02
B17: Terminal capex % revenue (going concern only) | C17: 0.014
B19: Fiscal year | D19: 2026 | E19: 2027 | F19: 2028 | G19: 2029 | H19: 2030 | I19: 2031 | J19: 2032 | K19: 2033 | L19: 2034 | M19: 2035 | N19: 2036 | O19: 2037 | P19: 2038 | Q19: 2039 | R19: 2040 | S19: 2041 | T19: 2042 | U19: 2043 | V19: 2044 | W19: 2045 | X19: 2046 | Y19: 2047 | Z19: 2048 | AA19: 2049 | AB19: 2050 | AC19: 2051 | AD19: 2052 | AE19: 2053 | AF19: 2054 | AG19: 2055 | AH19: 2056 | AI19: 2057 | AJ19: 2058 | AK19: 2059 | AL19: 2060 | AM19: 2061 | AN19: 2062 | AO19: 2063 | AP19: 2064 | AQ19: 2065 | AR19: 2066 | AS19: 2067 | AT19: 2068 | AU19: 2069 | AV19: 2070
B20: Fraction of year in valuation (after val. date / before concession end) | D20: =IF($C$13=1,MAX(0,MIN(DATE(D$19,12,31),$C$14)-MAX(Inputs!$C$5+1,DATE(D$19,1,1))+1)/365,IF(D$19<=$C$15,(DATE(D$19,12,31)-MAX(Inputs!$C$5+1,DATE(D$19,1,1))+1)/365,0)) -> 0.50410959 | E20: =IF($C$13=1,MAX(0,MIN(DATE(E$19,12,31),$C$14)-MAX(Inputs!$C$5+1,DATE(E$19,1,1))+1)/365,IF(E$19<=$C$15,(DATE(E$19,12,31)-MAX(Inputs!$C$5+1,DATE(E$19,1,1))+1)/365,0)) -> 1 | F20: =IF($C$13=1,MAX(0,MIN(DATE(F$19,12,31),$C$14)-MAX(Inputs!$C$5+1,DATE(F$19,1,1))+1)/365,IF(F$19<=$C$15,(DATE(F$19,12,31)-MAX(Inputs!$C$5+1,DATE(F$19,1,1))+1)/365,0)) -> 1.0027397 | G20: =IF($C$13=1,MAX(0,MIN(DATE(G$19,12,31),$C$14)-MAX(Inputs!$C$5+1,DATE(G$19,1,1))+1)/365,IF(G$19<=$C$15,(DATE(G$19,12,31)-MAX(Inputs!$C$5+1,DATE(G$19,1,1))+1)/365,0)) -> 1 | H20: =IF($C$13=1,MAX(0,MIN(DATE(H$19,12,31),$C$14)-MAX(Inputs!$C$5+1,DATE(H$19,1,1))+1)/365,IF(H$19<=$C$15,(DATE(H$19,12,31)-MAX(Inputs!$C$5+1,DATE(H$19,1,1))+1)/365,0)) -> 1 | I20: =IF($C$13=1,MAX(0,MIN(DATE(I$19,12,31),$C$14)-MAX(Inputs!$C$5+1,DATE(I$19,1,1))+1)/365,IF(I$19<=$C$15,(DATE(I$19,12,31)-MAX(Inputs!$C$5+1,DATE(I$19,1,1))+1)/365,0)) -> 0 | J20: =IF($C$13=1,MAX(0,MIN(DATE(J$19,12,31),$C$14)-MAX(Inputs!$C$5+1,DATE(J$19,1,1))+1)/365,IF(J$19<=$C$15,(DATE(J$19,12,31)-MAX(Inputs!$C$5+1,DATE(J$19,1,1))+1)/365,0)) -> 0 | K20: =IF($C$13=1,MAX(0,MIN(DATE(K$19,12,31),$C$14)-MAX(Inputs!$C$5+1,DATE(K$19,1,1))+1)/365,IF(K$19<=$C$15,(DATE(K$19,12,31)-MAX(Inputs!$C$5+1,DATE(K$19,1,1))+1)/365,0)) -> 0 | ... AV20: =IF($C$13=1,MAX(0,MIN(DATE(AV$19,12,31),$C$14)-MAX(Inputs!$C$5+1,DATE(AV$19,1,1))+1)/365,IF(AV$19<=$C$15,(DATE(AV$19,12,31)-MAX(Inputs!$C$5+1,DATE(AV$19,1,1))+1)/365,0)) -> 0
B21: Revenue (full-year run-rate) | D21: =$C$5*(1+$C$6) -> 23012.52 | E21: =D21*(1+$C$7) -> 24163.146 | F21: =E21*(1+$C$7) -> 25371.303 | G21: =F21*(1+$C$7) -> 26639.868 | H21: =G21*(1+$C$7) -> 27971.862 | I21: =H21*(1+$C$7) -> 29370.455 | J21: =I21*(1+$C$7) -> 30838.978 | K21: =J21*(1+$C$7) -> 32380.927 | L21: =K21*(1+$C$7) -> 33999.973 | ... AV21: =AU21*(1+$C$7) -> 196921.59
B22: EBITDA | D22: =D21*$C$8 -> 2149.3694 | E22: =E21*$C$8 -> 2256.8378 | F22: =F21*$C$8 -> 2369.6797 | G22: =G21*$C$8 -> 2488.1637 | H22: =H21*$C$8 -> 2612.5719 | I22: =I21*$C$8 -> 2743.2005 | J22: =J21*$C$8 -> 2880.3605 | K22: =K21*$C$8 -> 3024.3785 | ... AV22: =AV21*$C$8 -> 18392.477
B23: D&A | D23: =-D21*$C$9 -> -660.45932 | E23: =-E21*$C$9 -> -693.48229 | F23: =-F21*$C$9 -> -728.1564 | G23: =-G21*$C$9 -> -764.56422 | H23: =-H21*$C$9 -> -802.79244 | I23: =-I21*$C$9 -> -842.93206 | J23: =-J21*$C$9 -> -885.07866 | K23: =-K21*$C$9 -> -929.33259 | ... AV23: =-AV21*$C$9 -> -5651.6497
B24: EBIT | D24: =D22+D23 -> 1488.91 | E24: =E22+E23 -> 1563.3555 | F24: =F22+F23 -> 1641.5233 | G24: =G22+G23 -> 1723.5995 | H24: =H22+H23 -> 1809.7795 | I24: =I22+I23 -> 1900.2684 | J24: =J22+J23 -> 1995.2819 | K24: =K22+K23 -> 2095.046 | ... AV24: =AV22+AV23 -> 12740.827
B25: Tax rate | D25: =IF(D$19=2026,Inputs!$C$10,Inputs!$C$11) -> 0.348 | E25: =IF(E$19=2026,Inputs!$C$10,Inputs!$C$11) -> 0.258 | F25: =IF(F$19=2026,Inputs!$C$10,Inputs!$C$11) -> 0.258 | G25: =IF(G$19=2026,Inputs!$C$10,Inputs!$C$11) -> 0.258 | H25: =IF(H$19=2026,Inputs!$C$10,Inputs!$C$11) -> 0.258 | I25: =IF(I$19=2026,Inputs!$C$10,Inputs!$C$11) -> 0.258 | J25: =IF(J$19=2026,Inputs!$C$10,Inputs!$C$11) -> 0.258 | K25: =IF(K$19=2026,Inputs!$C$10,Inputs!$C$11) -> 0.258 | ... AV25: =IF(AV$19=2026,Inputs!$C$10,Inputs!$C$11) -> 0.258
B26: Tax on EBIT | D26: =-MAX(0,D24)*D25 -> -518.1407 | E26: =-MAX(0,E24)*E25 -> -403.34573 | F26: =-MAX(0,F24)*F25 -> -423.51302 | G26: =-MAX(0,G24)*G25 -> -444.68867 | H26: =-MAX(0,H24)*H25 -> -466.9231 | I26: =-MAX(0,I24)*I25 -> -490.26926 | J26: =-MAX(0,J24)*J25 -> -514.78272 | K26: =-MAX(0,K24)*K25 -> -540.52186 | ... AV26: =-MAX(0,AV24)*AV25 -> -3287.1334
B27: Capex | D27: =-D21*$C$10 -> -299.16276 | E27: =-E21*$C$10 -> -314.1209 | F27: =-F21*$C$10 -> -329.82694 | G27: =-G21*$C$10 -> -346.31829 | H27: =-H21*$C$10 -> -363.6342 | I27: =-I21*$C$10 -> -381.81591 | J27: =-J21*$C$10 -> -400.90671 | K27: =-K21*$C$10 -> -420.95205 | ... AV27: =-AV21*$C$10 -> -2559.9807
B28: Lease repayments | D28: =-D21*$C$11 -> -474.05791 | E28: =-E21*$C$11 -> -497.76081 | F28: =-F21*$C$11 -> -522.64885 | G28: =-G21*$C$11 -> -548.78129 | H28: =-H21*$C$11 -> -576.22035 | I28: =-I21*$C$11 -> -605.03137 | J28: =-J21*$C$11 -> -635.28294 | K28: =-K21*$C$11 -> -667.04709 | ... AV28: =-AV21*$C$11 -> -4056.5848
B29: Unlevered FCF in valuation window | D29: =(D22+D26+D27+D28)*D20 -> 432.53006 | E29: =(E22+E26+E27+E28)*E20 -> 1041.6104 | F29: =(F22+F26+F27+F28)*F20 -> 1096.6873 | G29: =(G22+G26+G27+G28)*G20 -> 1148.3755 | H29: =(H22+H26+H27+H28)*H20 -> 1205.7942 | I29: =(I22+I26+I27+I28)*I20 -> 0 | J29: =(J22+J26+J27+J28)*J20 -> 0 | K29: =(K22+K26+K27+K28)*K20 -> 0 | ... AV29: =(AV22+AV26+AV27+AV28)*AV20 -> 0
B30: Discount period (mid-period, years) | D30: =((MAX(Inputs!$C$5+1,DATE(D$19,1,1))+DATE(D$19,12,31))/2-Inputs!$C$5)/365 -> 0.25342466 | E30: =((MAX(Inputs!$C$5+1,DATE(E$19,1,1))+DATE(E$19,12,31))/2-Inputs!$C$5)/365 -> 1.0054795 | F30: =((MAX(Inputs!$C$5+1,DATE(F$19,1,1))+DATE(F$19,12,31))/2-Inputs!$C$5)/365 -> 2.0068493 | G30: =((MAX(Inputs!$C$5+1,DATE(G$19,1,1))+DATE(G$19,12,31))/2-Inputs!$C$5)/365 -> 3.0082192 | H30: =((MAX(Inputs!$C$5+1,DATE(H$19,1,1))+DATE(H$19,12,31))/2-Inputs!$C$5)/365 -> 4.0082192 | I30: =((MAX(Inputs!$C$5+1,DATE(I$19,1,1))+DATE(I$19,12,31))/2-Inputs!$C$5)/365 -> 5.0082192 | J30: =((MAX(Inputs!$C$5+1,DATE(J$19,1,1))+DATE(J$19,12,31))/2-Inputs!$C$5)/365 -> 6.009589 | K30: =((MAX(Inputs!$C$5+1,DATE(K$19,1,1))+DATE(K$19,12,31))/2-Inputs!$C$5)/365 -> 7.0109589 | ... AV30: =((MAX(Inputs!$C$5+1,DATE(AV$19,1,1))+DATE(AV$19,12,31))/2-Inputs!$C$5)/365 -> 44.035616
B31: Discount factor | D31: =1/(1+$C$12)^D30 -> 0.98183909 | E31: =1/(1+$C$12)^E30 -> 0.929864 | F31: =1/(1+$C$12)^F30 -> 0.86490408 | G31: =1/(1+$C$12)^G30 -> 0.80448223 | H31: =1/(1+$C$12)^H30 -> 0.74835556 | I31: =1/(1+$C$12)^I30 -> 0.69614471 | J31: =1/(1+$C$12)^J30 -> 0.64751232 | K31: =1/(1+$C$12)^K30 -> 0.60227737 | ... AV31: =1/(1+$C$12)^AV30 -> 0.041391286
B32: PV of UFCF | D32: =D29*D31 -> 424.67492 | E32: =E29*E31 -> 968.55601 | F32: =F29*F31 -> 948.52935 | G32: =G29*G31 -> 923.84766 | H32: =H29*H31 -> 902.36283 | I32: =I29*I31 -> 0 | J32: =J29*J31 -> 0 | K32: =K29*K31 -> 0 | ... AV32: =AV29*AV31 -> 0
B33: Terminal-year normalised FCF (before growth) | D33: =IF(AND($C$13=0,D$19=$C$15),D22-D21*($C$17+$C$11)-MAX(0,D22-D21*$C$17)*Inputs!$C$11,0) -> 0 | E33: =IF(AND($C$13=0,E$19=$C$15),E22-E21*($C$17+$C$11)-MAX(0,E22-E21*$C$17)*Inputs!$C$11,0) -> 0 | F33: =IF(AND($C$13=0,F$19=$C$15),F22-F21*($C$17+$C$11)-MAX(0,F22-F21*$C$17)*Inputs!$C$11,0) -> 0 | G33: =IF(AND($C$13=0,G$19=$C$15),G22-G21*($C$17+$C$11)-MAX(0,G22-G21*$C$17)*Inputs!$C$11,0) -> 0 | H33: =IF(AND($C$13=0,H$19=$C$15),H22-H21*($C$17+$C$11)-MAX(0,H22-H21*$C$17)*Inputs!$C$11,0) -> 1071.7363 | I33: =IF(AND($C$13=0,I$19=$C$15),I22-I21*($C$17+$C$11)-MAX(0,I22-I21*$C$17)*Inputs!$C$11,0) -> 0 | J33: =IF(AND($C$13=0,J$19=$C$15),J22-J21*($C$17+$C$11)-MAX(0,J22-J21*$C$17)*Inputs!$C$11,0) -> 0 | K33: =IF(AND($C$13=0,K$19=$C$15),K22-K21*($C$17+$C$11)-MAX(0,K22-K21*$C$17)*Inputs!$C$11,0) -> 0 | ... AV33: =IF(AND($C$13=0,AV$19=$C$15),AV22-AV21*($C$17+$C$11)-MAX(0,AV22-AV21*$C$17)*Inputs!$C$11,0) -> 0
B34: PV of terminal value | D34: =D33*(1+$C$16)/($C$12-$C$16)*D31 -> 0 | E34: =E33*(1+$C$16)/($C$12-$C$16)*E31 -> 0 | F34: =F33*(1+$C$16)/($C$12-$C$16)*F31 -> 0 | G34: =G33*(1+$C$16)/($C$12-$C$16)*G31 -> 0 | H34: =H33*(1+$C$16)/($C$12-$C$16)*H31 -> 14874.193 | I34: =I33*(1+$C$16)/($C$12-$C$16)*I31 -> 0 | J34: =J33*(1+$C$16)/($C$12-$C$16)*J31 -> 0 | K34: =K33*(1+$C$16)/($C$12-$C$16)*K31 -> 0 | ... AV34: =AV33*(1+$C$16)/($C$12-$C$16)*AV31 -> 0
B36: PV of explicit / concession-life cash flows | C36: =SUM($D$32:$AV$32) -> 4167.9708
B37: PV of terminal value | C37: =SUM($D$34:$AV$34) -> 14874.193
B38: ENTERPRISE VALUE — VINCI Energies (100%) | C38: =C36+C37 -> 19042.164
B39: Terminal value as % of block EV | C39: =IF(C38=0,0,C37/C38) -> 0.78111885
B40: Implied EV / FY2026E EBITDA | C40: =IF(D22=0,0,C38/D22) -> 8.859419
B41: Terminal FCF base (for sensitivity) | C41: =SUM($D$33:$AV$33) -> 1071.7363
B42: Terminal discount period (for sensitivity) | C42: =SUMPRODUCT(($D$19:$AV$19=$C$15)*$D$30:$AV$30) -> 4.0082192
B43: Check: WACC > g and no cash flow after concession end | C43: =IF(AND($C$12>$C$16,SUMPRODUCT(($D$19:$AV$19>YEAR($C$14))*($C$13=1)*ABS($D$29:$AV$29))=0),"OK","REVISAR") -> OK
B46: Cobra IS
...

Sheet Historicals
B2: Vinci SA — Historicals & Sources (all figures EUR millions unless noted)
B3: Source: Vinci SA FY2025 Consolidated Financial Statements (year ended 31-Dec-2025), p.3 unless noted
B5: 1. Income Statement (exact Vinci cascade, p.3)
C6: FY2025 | D6: FY2024 | E6: FY2023
B7: Revenue | C7: 74599 | D7: 71623 | E7: 68838
B8: Concession subsidiaries' revenue derived from works | C8: 772 | D8: 837 | E8: 780
B9: Total revenue | C9: 75372 | D9: 72459 | E9: 69619
B10: Check: Revenue + Concession works = Total revenue? | C10: =IF(ABS(C7+C8-C9)<=1,"OK (rounding)","REVIEW") -> OK (rounding) | D10: =IF(ABS(D7+D8-D9)<=1,"OK (rounding)","REVIEW") -> OK (rounding) | E10: =IF(ABS(E7+E8-E9)<=1,"OK (rounding)","REVIEW") -> OK (rounding)
B12: Revenue from ancillary activities | C12: 331 | D12: 308 | E12: 267
B13: Operating expenses | C13: -66145 | D13: -63770 | E13: -61529
B14: Operating income from ordinary activities (EBIT) | C14: 9558 | D14: 8997 | E14: 8357
B15: Check: cascade to EBIT ties out? | C15: =IF(ABS(C9+C12+C13-C14)<=1,"OK","REVIEW") -> OK | D15: =IF(ABS(D9+D12+D13-D14)<=1,"OK","REVIEW") -> OK | E15: =IF(ABS(E9+E12+E13-E14)<=1,"OK","REVIEW") -> OK
B16: EBIT margin % (of Revenue) | C16: =C14/C7 -> 0.12812504 | D16: =D14/D7 -> 0.12561607 | E16: =E14/E7 -> 0.12140097
B18: Share-based payments (IFRS 2) | C18: -567 | D18: -462 | E18: -360
B19: Profit/(loss) of companies accounted for under the equity method | C19: 300 | D19: 219 | E19: 111
B20: Other recurring operating items | C20: 110 | D20: 97 | E20: 68
B21: Recurring operating income | C21: 9401 | D21: 8850 | E21: 8175
B22: Non-recurring operating items | C22: -37 | D22: -68 | E22: -105
B23: Operating income | C23: 9364 | D23: 8783 | E23: 8071
B25: Cost of gross financial debt | C25: -1760 | D25: -1785 | E25: -1363
B26: Financial income from cash investments | C26: 513 | D26: 595 | E26: 469
B27: Cost of net financial debt | C27: -1247 | D27: -1191 | E27: -894
B28: Other financial income and expense | C28: -181 | D28: -217 | E28: -157
B29: Income before tax and profit of equity-method cos. (matches Vinci tax note basis) | C29: =C23+C27+C28-C19 -> 7636 | D29: =D23+D27+D28-D19 -> 7156 | E29: =E23+E27+E28 -> 7020
B30: Income tax expense | C30: -2661 | D30: -2102 | E30: -1917
B31: Effective tax rate (cross-check only, not used in DCF) | C31: =-C30/C29 -> 0.34848088 | D31: =-D30/D29 -> 0.29373952 | E31: =-E30/E29 -> 0.27307692
B32: Net income | C32: 5275 | D32: 5274 | E32: 5102
B33: Net income attributable to non-controlling interests | C33: 372 | D33: 410 | E33: 400
B34: Net income attributable to owners of the parent | C34: 4903 | D34: 4863 | E34: 4702
B36: Depreciation & amortisation (D&A) | C36: 4206 | D36: 3998 | E36: 3799
B37: D&A % of Revenue | C37: =C36/C7 -> 0.056381453 | D37: =D36/D7 -> 0.055820058 | E37: =E36/E7 -> 0.055187542
B38: EBITDA (memo = EBIT + D&A) | C38: =C14+C36 -> 13764 | D38: =D14+D36 -> 12995 | E38: =E14+E36 -> 12156
B39: EBITDA margin % | C39: =C38/C7 -> 0.18450649 | D39: =D38/D7 -> 0.18143613 | E39: =E38/E7 -> 0.17658851
B41: Per-Share Data (memo — for trading comps / share count cross-check, not used in UFCF)
B42: Basic EPS (EUR) | C42: 8.76 | D42: 8.53 | E42: 8.28
B43: Diluted EPS (EUR) | C43: 8.65 | D43: 8.43 | E43: 8.18
B44: Implied basic shares outstanding (mm) — cross-check | C44: =C34/C42 -> 559.7032 | D44: =D34/D42 -> 570.10551 | E44: =E34/E42 -> 567.8744
B45: Implied diluted shares outstanding (mm) — cross-check | C45: =C34/C43 -> 566.82081 | D45: =D34/D43 -> 576.86833 | E45: =E34/E43 -> 574.81663
B47: 1b. Tax Rate — Methodology & Sourcing
B48: French theoretical CIT rate (excl. exceptional contribution) — per Vinci's own tax note | C48: 0.258
...
