Workbook

Sheet README
B1: Vinci SA — DCF Valuation
B2: Euronext Paris: DG · EUR millions · Valuation date 4 Jul 2026
B4: Context
B5: Motorway and airport concessions, energy and construction — the clearest fit for the civil-engineering-to-infrastructure angle, operating the same assets an engineer trains to build. Anchor of a three-company European PUI portfolio (with National Grid and Ferrovial).
B7: Methodology
B8: Unlevered DCF off three tied-out years of historicals (FY2023–25). Stub + mid-year discounting, dual terminal value (Gordon Growth + exit multiple) cross-checked, net-debt WACC weights.
B10: Key assumptions
B11: WACC 5.98% (CoE 6.75%, after-tax CoD 3.26%)
B12: Rf 2.99% (ECB AAA 10Y, 2 Jul 2026) · Beta 0.75 · ERP 5.01% (Damodaran, France)
B13: Cost of debt 4.4% pre-tax (Vinci's own disclosed average, FY2025)
B14: Tax 25.8% long-run; 34.8% in FY2026 (French temporary surtax)
B15: Net debt €19,075m · Diluted shares 530.01m
... B33: 1 of 3: Vinci (anchor) · National Grid (regulated utility) · Ferrovial (concessions + SOTP).

Sheet Historicals
B2: Vinci SA — Historicals & Sources (all figures EUR millions unless noted)
B3: Source: Vinci SA FY2025 Consolidated Financial Statements (year ended 31-Dec-2025), p.3 unless noted
B5: 1. Income Statement (exact Vinci cascade, p.3)
C6: FY2025 | D6: FY2024 | E6: FY2023
B7: Revenue | C7: 74599 | D7: 71623 | E7: 68838
B8: Concession subsidiaries' revenue derived from works | C8: 772 | D8: 837 | E8: 780
B9: Total revenue | C9: 75372 | D9: 72459 | E9: 69619
B10: Check: Revenue + Concession works = Total revenue? | C10: =IF(ABS(C7+C8-C9)<=1,"OK (rounding)","REVIEW") -> OK (rounding) | D10: =IF(ABS(D7+D8-D9)<=1,"OK (rounding)","REVIEW") -> OK (rounding) | E10: =IF(ABS(E7+E8-E9)<=1,"OK (rounding)","REVIEW") -> OK (rounding)
B12: Revenue from ancillary activities | C12: 331 | D12: 308 | E12: 267
B13: Operating expenses | C13: -66145 | D13: -63770 | E13: -61529
B14: Operating income from ordinary activities (EBIT) | C14: 9558 | D14: 8997 | E14: 8357
B15: Check: cascade to EBIT ties out? | C15: =IF(ABS(C9+C12+C13-C14)<=1,"OK","REVIEW") -> OK | D15: =IF(ABS(D9+D12+D13-D14)<=1,"OK","REVIEW") -> OK | E15: =IF(ABS(E9+E12+E13-E14)<=1,"OK","REVIEW") -> OK
B16: EBIT margin % (of Revenue) | C16: =C14/C7 -> 0.12812504 | D16: =D14/D7 -> 0.12561607 | E16: =E14/E7 -> 0.12140097
B18: Share-based payments (IFRS 2) | C18: -567 | D18: -462 | E18: -360
B19: Profit/(loss) of companies accounted for under the equity method | C19: 300 | D19: 219 | E19: 111
B20: Other recurring operating items | C20: 110 | D20: 97 | E20: 68
B21: Recurring operating income | C21: 9401 | D21: 8850 | E21: 8175
B22: Non-recurring operating items | C22: -37 | D22: -68 | E22: -105
B23: Operating income | C23: 9364 | D23: 8783 | E23: 8071
B25: Cost of gross financial debt | C25: -1760 | D25: -1785 | E25: -1363
B26: Financial income from cash investments | C26: 513 | D26: 595 | E26: 469
B27: Cost of net financial debt | C27: -1247 | D27: -1191 | E27: -894
B28: Other financial income and expense | C28: -181 | D28: -217 | E28: -157
B29: Income before tax and profit of equity-method cos. (matches Vinci tax note basis) | C29: =C23+C27+C28-C19 -> 7636 | D29: =D23+D27+D28-D19 -> 7156 | E29: =E23+E27+E28 -> 7020
B30: Income tax expense | C30: -2661 | D30: -2102 | E30: -1917
B31: Effective tax rate (cross-check only, not used in DCF) | C31: =-C30/C29 -> 0.34848088 | D31: =-D30/D29 -> 0.29373952 | E31: =-E30/E29 -> 0.27307692
B32: Net income | C32: 5275 | D32: 5274 | E32: 5102
B33: Net income attributable to non-controlling interests | C33: 372 | D33: 410 | E33: 400
B34: Net income attributable to owners of the parent | C34: 4903 | D34: 4863 | E34: 4702
B36: Depreciation & amortisation (D&A) | C36: 4206 | D36: 3998 | E36: 3799
B37: D&A % of Revenue | C37: =C36/C7 -> 0.056381453 | D37: =D36/D7 -> 0.055820058 | E37: =E36/E7 -> 0.055187542
B38: EBITDA (memo = EBIT + D&A) | C38: =C14+C36 -> 13764 | D38: =D14+D36 -> 12995 | E38: =E14+E36 -> 12156
B39: EBITDA margin % | C39: =C38/C7 -> 0.18450649 | D39: =D38/D7 -> 0.18143613 | E39: =E38/E7 -> 0.17658851
B41: Per-Share Data (memo — for trading comps / share count cross-check, not used in UFCF)
B42: Basic EPS (EUR) | C42: 8.76 | D42: 8.53 | E42: 8.28
B43: Diluted EPS (EUR) | C43: 8.65 | D43: 8.43 | E43: 8.18
B44: Implied basic shares outstanding (mm) — cross-check | C44: =C34/C42 -> 559.7032 | D44: =D34/D42 -> 570.10551 | E44: =E34/E42 -> 567.8744
B45: Implied diluted shares outstanding (mm) — cross-check | C45: =C34/C43 -> 566.82081 | D45: =D34/D43 -> 576.86833 | E45: =E34/E43 -> 574.81663
B47: 1b. Tax Rate — Methodology & Sourcing
B48: French theoretical CIT rate (excl. exceptional contribution) — per Vinci's own tax note | C48: 0.258
...

Sheet WACC
B2: WACC Buildup
B3: =Historicals!B2 -> Vinci SA — Historicals & Sources (all figures EUR millions unless noted)
B4: Cost of capital assumptions
I5: Source
B6: Cost of debt | C6: =Historicals!C205 -> 0.044 | I6: Vinci's own disclosed average cost of long-term gross financial debt (4.4%, FY2025) — see Historicals Sec.7
B7: Tax rate | C7: =Historicals!C54 -> 0.258 | I7: Long-run French statutory rate (25%) — WACC discounts a perpetual stream, so the LONG-RUN rate is used here, not the ~35% near-term rate reflecting France's temporary FY2025-26 large-company surtax (that surtax is instead applied directly in the DCF tab's explicit-forecast tax schedule).
B8: Cost of debt (after tax) | C8: =C6*(1-C7) -> 0.032648 | I8: Cost of debt x (1 - tax rate)
B10: Risk free rate | C10: 0.02988 | I10: ECB euro-area AAA-rated bond yield curve, spot rate, 10yr tenor, 2-Jul-2026
B11: Beta | C11: =Historicals!C199 -> 0.75 | I11: stockanalysis.com, DG.PA, 5Y monthly (proxy for Bloomberg 2Y weekly convention)
B12: Market risk premium | C12: 0.0501 | I12: Damodaran Country Risk Premium dataset, France, rating-based Total ERP, queried 4-Jul-2026
B13: Cost of equity | C13: =C10+C11*C12 -> 0.067455 | I13: RfR + Beta x MRP
B15: Capital weights (capital structure)
C16: Current | D16: % of total
B18: Equity | C18: =Historicals!C197 -> 67790 | D18: =C18/(C18+C19) -> 0.78040638
B19: Debt (net) | C19: =Historicals!C191 -> 19075 | D19: =1-D18 -> 0.21959362 | I19: NET debt (not gross), matching the WSP reference workbook convention (WACC Done!C19 links to net debt).
B21: Cost of capital (WACC) | C21: =C8*D19+C13*D18 -> 0.059811605
B23: WACC sensitivity to MRP and Beta
D24: Beta
C25: =C21 -> 0.059811605 | D25: =$C$11-0.1 -> 0.65 | E25: =$C$11-0.05 -> 0.7 | F25: =$C$11 -> 0.75 | G25: =$C$11+0.05 -> 0.8 | H25: =$C$11+0.1 -> 0.85
C26: =$C$12-0.005 -> 0.0451 | D26: =$C$8*$D$19+($C$10+D$25*$C26)*$D$18 -> 0.053365448 | E26: =$C$8*$D$19+($C$10+E$25*$C26)*$D$18 -> 0.055125264 | F26: =$C$8*$D$19+($C$10+F$25*$C26)*$D$18 -> 0.056885081 | G26: =$C$8*$D$19+($C$10+G$25*$C26)*$D$18 -> 0.058644897 | H26: =$C$8*$D$19+($C$10+H$25*$C26)*$D$18 -> 0.060404714
B27: Market | C27: =$C$12-0.0025 -> 0.0476 | D27: =$C$8*$D$19+($C$10+D$25*$C27)*$D$18 -> 0.054633608 | E27: =$C$8*$D$19+($C$10+E$25*$C27)*$D$18 -> 0.056490976 | F27: =$C$8*$D$19+($C$10+F$25*$C27)*$D$18 -> 0.058348343 | G27: =$C$8*$D$19+($C$10+G$25*$C27)*$D$18 -> 0.06020571 | H27: =$C$8*$D$19+($C$10+H$25*$C27)*$D$18 -> 0.062063077
B28: Risk | C28: =$C$12 -> 0.0501 | D28: =$C$8*$D$19+($C$10+D$25*$C28)*$D$18 -> 0.055901769 | E28: =$C$8*$D$19+($C$10+E$25*$C28)*$D$18 -> 0.057856687 | F28: =$C$8*$D$19+($C$10+F$25*$C28)*$D$18 -> 0.059811605 | G28: =$C$8*$D$19+($C$10+G$25*$C28)*$D$18 -> 0.061766523 | H28: =$C$8*$D$19+($C$10+H$25*$C28)*$D$18 -> 0.063721441
B29: Premium | C29: =$C$12+0.0025 -> 0.0526 | D29: =$C$8*$D$19+($C$10+D$25*$C29)*$D$18 -> 0.057169929 | E29: =$C$8*$D$19+($C$10+E$25*$C29)*$D$18 -> 0.059222398 | F29: =$C$8*$D$19+($C$10+F$25*$C29)*$D$18 -> 0.061274867 | G29: =$C$8*$D$19+($C$10+G$25*$C29)*$D$18 -> 0.063327336 | H29: =$C$8*$D$19+($C$10+H$25*$C29)*$D$18 -> 0.065379804
C30: =$C$12+0.005 -> 0.0551 | D30: =$C$8*$D$19+($C$10+D$25*$C30)*$D$18 -> 0.05843809 | E30: =$C$8*$D$19+($C$10+E$25*$C30)*$D$18 -> 0.060588109 | F30: =$C$8*$D$19+($C$10+F$25*$C30)*$D$18 -> 0.062738129 | G30: =$C$8*$D$19+($C$10+G$25*$C30)*$D$18 -> 0.064888148 | H30: =$C$8*$D$19+($C$10+H$25*$C30)*$D$18 -> 0.067038168

Sheet DCF
B2: Discounted Cash Flow Valuation
B3: =Historicals!B2 -> Vinci SA — Historicals & Sources (all figures EUR millions unless noted)
B4: Most recent fiscal year end | D4: 46022 | F4: Discount rate (WACC) | H4: =WACC!C21 -> 0.059811605
B5: End of first fiscal year | D5: =EOMONTH(D4,12) -> 46387 | F5: Share price (Public Co) | H5: =Historicals!C195 -> 126.9
B6: Most recent quarter end date | D6: 46022 | F6: Share price date | H6: 46207
B7: Valuation date | D7: 46207 | F7: Midyear adjustment? | H7: 1
B8: Portion of year 1 cash flows in forecast | D8: =YEARFRAC(D7,D5) -> 0.49166667
B10: Unlevered Free Cash Flows
D11: Actual | E11: Forecasts
B12: Fiscal year ended | D12: =D4 -> 46022 | E12: =EOMONTH(D12,12) -> 46387 | F12: =EOMONTH(E12,12) -> 46752 | G12: =EOMONTH(F12,12) -> 47118 | H12: =EOMONTH(G12,12) -> 47483 | I12: =EOMONTH(H12,12) -> 47848
B14: Revenue | D14: =Historicals!C7 -> 74599 | E14: =D14*(1+E15) -> 77582.96 | F14: =E14*(1+F15) -> 80686.278 | G14: =F14*(1+G15) -> 83510.298 | H14: =G14*(1+H15) -> 86433.159 | I14: =H14*(1+I15) -> 89026.153
B15: % growth | E15: 0.04 | F15: 0.04 | G15: 0.035 | H15: 0.035 | I15: 0.03
B16: EBITDA | D16: =D18+D25 -> 13764 | E16: =E17*E14 -> 14275.265 | F16: =F17*F14 -> 14846.275 | G16: =G17*G14 -> 15365.895 | H16: =H17*H14 -> 15990.134 | I16: =I17*I14 -> 16469.838
B17: % margin | D17: =D16/D14 -> 0.18450649 | E17: 0.184 | F17: 0.184 | G17: 0.184 | H17: 0.185 | I17: 0.185
B18: EBIT | D18: =Historicals!C14 -> 9558 | E18: =E19*E14 -> 9930.6189 | F18: =F19*F14 -> 10408.53 | G18: =G19*G14 -> 10856.339 | H18: =H19*H14 -> 11236.311 | I18: =I19*I14 -> 11573.4
B19: % margin | D19: =D18/D14 -> 0.12812504 | E19: 0.128 | F19: 0.129 | G19: 0.13 | H19: 0.13 | I19: 0.13
B21: Tax on EBIT | D21: =D22*D18 -> 3326.184 | E21: =E22*E18 -> 3455.8554 | F21: =F22*F18 -> 2685.4007 | G21: =G22*G18 -> 2800.9354 | H21: =H22*H18 -> 2898.9681 | I21: =I22*I18 -> 2985.9372
B22: Tax rate | D22: =Historicals!C50 -> 0.348 | E22: =Historicals!C53 -> 0.348 | F22: =Historicals!C54 -> 0.258 | G22: =Historicals!C54 -> 0.258 | H22: =Historicals!C54 -> 0.258 | I22: =Historicals!C54 -> 0.258
B23: NOPAT (aka EBIAT) | D23: =D18-D21 -> 6231.816 | E23: =E18-E21 -> 6474.7635 | F23: =F18-F21 -> 7723.1292 | G23: =G18-G21 -> 8055.4034 | H23: =H18-H21 -> 8337.3425 | I23: =I18-I21 -> 8587.4628
B25: Depreciation & amortization | D25: =Historicals!C36 -> 4206 | E25: =E16-E18 -> 4344.6458 | F25: =F16-F18 -> 4437.7453 | G25: =G16-G18 -> 4509.5561 | H25: =H16-H18 -> 4753.8237 | I25: =I16-I18 -> 4896.4384
B26: Changes in net working capital | D26: =C32-D32 -> 2399 | E26: =D32-E32 -> 774.56 | F26: =E32-F32 -> 805.5424 | G26: =F32-G32 -> 733.04358 | H26: =G32-H32 -> 758.70011 | I26: =H32-I32 -> 673.07538
B27: Capital expenditures | D27: =Historicals!C149 -> -4005 | E27: =-(E28*E14) -> -4267.0628 | F27: =-(F28*F14) -> -4437.7453 | G27: =-(G28*G14) -> -4509.5561 | H27: =-(H28*H14) -> -4667.3906 | I27: =-(I28*I14) -> -4945.4028
B28: as % of revenue | D28: =-(D27/D14) -> 0.053687047 | E28: 0.055 | F28: 0.055 | G28: 0.054 | H28: 0.054 | I28: =(I25/I14)*(1+C42) -> 0.05555
B30: Unlevered free cash flows (UFCF) | E30: =E23+E25+E26+E27 -> 7326.9065 | F30: =F23+F25+F26+F27 -> 8528.6716 | G30: =G23+G25+G26+G27 -> 8788.4469 | H30: =H23+H25+H26+H27 -> 9182.4757 | I30: =I23+I25+I26+I27 -> 9211.5737
B32: Net working capital (WC Assets - WC liabilities) | C32: =Historicals!D181 -> -16965 | D32: =Historicals!C181 -> -19364 | E32: =E33*E14 -> -20138.56 | F32: =F33*F14 -> -20944.102 | G32: =G33*G14 -> -21677.146 | H32: =H33*H14 -> -22435.846 | I32: =I33*I14 -> -23108.921
B33: as % of revenue | D33: =D32/D14 -> -0.25957453 | E33: =D33 -> -0.25957453 | F33: =E33 -> -0.25957453 | G33: =F33 -> -0.25957453 | H33: =G33 -> -0.25957453 | I33: =H33 -> -0.25957453
B35: Present value of UFCF on valuation date
D36: Val date | E36: Yr 1 - Stub | F36: Year 2 | G36: Year 3 | H36: Year 4 | I36: Year 5
B37: Date for discounting cash flows | D37: =D7 -> 46207 | E37: =IF($H$7=0,E12,AVERAGE(D37,E12)) -> 46297 | F37: =IF($H$7=0,F12,AVERAGE(E37,F12)) -> 46524.5 | G37: =IF($H$7=0,G12,AVERAGE(F37,G12)) -> 46821.25 | H37: =IF($H$7=0,H12,AVERAGE(G37,H12)) -> 47152.125 | I37: =IF($H$7=0,I12,AVERAGE(H37,I12)) -> 47500.062
B38: Unlevered free cash flows (UFCF) stub adjusted | C38: =D8 -> 0.49166667 | E38: =$C$38*E30 -> 3602.3957 | F38: =F30 -> 8528.6716 | G38: =G30 -> 8788.4469 | H38: =H30 -> 9182.4757 | I38: =I30 -> 9211.5737
B39: Present value of unlevered free cash flows | E39: =E38/(1+$H$4)^((E37-$D$37)/365) -> 3551.1633 | F39: =F38/(1+$H$4)^((F37-$D$37)/365) -> 8108.4138 | G39: =G38/(1+$H$4)^((G37-$D$37)/365) -> 7969.9463 | H39: =H38/(1+$H$4)^((H37-$D$37)/365) -> 7900.109 | I39: =I38/(1+$H$4)^((I37-$D$37)/365) -> 7498.2137
B41: Terminal value - growth in perpetuity approach | E41: Terminal value - EBITDA multiple approach
B42: Long term growth rate | C42: 0.01 | E42: Terminal year EBITDA | I42: =I16 -> 16469.838
B43: =YEAR(I12)&" FCF x (1+g)" -> 2030 FCF x (1+g) | C43: =I30*(1+C42) -> 9303.6895 | E43: EBITDA multiple | I43: 10.5
B44: ="Terminal value in "&YEAR(I12) -> Terminal value in 2030 | C44: =C43/(H4-C42) -> 186777.55 | E44: ="Terminal value in "&YEAR(I12) -> Terminal value in 2030 | I44: =I42*I43 -> 172933.3
B45: Present value of terminal value | C45: =C44/(1+H4)^((I37-D37)/365) -> 152036.78 | E45: Present value of terminal value | I45: =I44/(1+H4)^((I37-D37)/365) -> 140767.57
B46: Present value of stage 1 cash flows | C46: =SUM(E39:I39) -> 35027.846 | E46: Present value of stage 1 cash flows | I46: =C46 -> 35027.846
B47: Total enterprise value (TEV) | C47: =SUM(C45:C46) -> 187064.62 | E47: Enterprise value (stage 1 + 2) | I47: =SUM(I45:I46) -> 175795.42
B49: Terminal value as % of TEV | C49: =C45/$C$47 -> 0.81275002 | E49: Terminal value as % of TEV | I49: =I45/$I$47 -> 0.80074653
B50: Stage 1 cash flows as % of TEV | C50: =C46/$C$47 -> 0.18724998 | E50: Stage 1 cash flows as % of TEV | I50: =I46/$I$47 -> 0.19925347
...
